{
 "cells": [
  {
   "cell_type": "markdown",
   "metadata": {},
   "source": [
    "Resources Used\n",
    "- wget.download('https://tensorflow-object-detection-api-tutorial.readthedocs.io/en/latest/_downloads/da4babe668a8afb093cc7776d7e630f3/generate_tfrecord.py')\n",
    "- Setup https://tensorflow-object-detection-api-tutorial.readthedocs.io/en/latest/install.html"
   ]
  },
  {
   "cell_type": "markdown",
   "metadata": {},
   "source": [
    "# 0. Setup Paths"
   ]
  },
  {
   "cell_type": "code",
   "execution_count": 1,
   "metadata": {},
   "outputs": [],
   "source": [
    "WORKSPACE_PATH = 'Tensorflow/workspace'\n",
    "SCRIPTS_PATH = 'Tensorflow/scripts'\n",
    "APIMODEL_PATH = 'Tensorflow/models'\n",
    "ANNOTATION_PATH = WORKSPACE_PATH+'/annotations'\n",
    "IMAGE_PATH = WORKSPACE_PATH+'/images'\n",
    "MODEL_PATH = WORKSPACE_PATH+'/models'\n",
    "PRETRAINED_MODEL_PATH = WORKSPACE_PATH+'/pre-trained-models'\n",
    "CONFIG_PATH = MODEL_PATH+'/my_ssd_mobnet/pipeline.config'\n",
    "CHECKPOINT_PATH = MODEL_PATH+'/my_ssd_mobnet/'"
   ]
  },
  {
   "cell_type": "markdown",
   "metadata": {},
   "source": [
    "# 1. Create Label Map"
   ]
  },
  {
   "cell_type": "code",
   "execution_count": 5,
   "metadata": {},
   "outputs": [],
   "source": [
    "labels = [\n",
    "    {'name':'o', 'id':1},\n",
    "    {'name':\"r\", 'id':2}\n",
    "]\n",
    "\n",
    "with open(ANNOTATION_PATH + '\\label_map.pbtxt', 'w',encoding='utf-8') as f:\n",
    "    for label in labels:\n",
    "        f.write('item { \\n')\n",
    "        f.write('\\tname:\\'{}\\'\\n'.format(label['name']))\n",
    "        f.write('\\tid:{}\\n'.format(label['id']))\n",
    "        f.write('}\\n')"
   ]
  },
  {
   "cell_type": "markdown",
   "metadata": {},
   "source": [
    "# 2. Create TF records"
   ]
  },
  {
   "cell_type": "code",
   "execution_count": 19,
   "metadata": {},
   "outputs": [
    {
     "name": "stdout",
     "output_type": "stream",
     "text": [
      "ERROR! Session/line number was not unique in database. History logging moved to new session 74\n"
     ]
    },
    {
     "name": "stderr",
     "output_type": "stream",
     "text": [
      "Traceback (most recent call last):\n",
      "  File \"Tensorflow/scripts/generate_tfrecord.py\", line 62, in <module>\n",
      "    label_map_dict = label_map_util.get_label_map_dict(label_map)\n",
      "  File \"D:\\OneDrive\\RealTimeObjectDetection\\tensor\\lib\\site-packages\\object_detection\\utils\\label_map_util.py\", line 164, in get_label_map_dict\n",
      "    label_map = load_labelmap(label_map_path)\n",
      "  File \"D:\\OneDrive\\RealTimeObjectDetection\\tensor\\lib\\site-packages\\object_detection\\utils\\label_map_util.py\", line 133, in load_labelmap\n",
      "    label_map_string = fid.read()\n",
      "  File \"D:\\OneDrive\\RealTimeObjectDetection\\tensor\\lib\\site-packages\\tensorflow_core\\python\\lib\\io\\file_io.py\", line 122, in read\n",
      "    self._preread_check()\n",
      "  File \"D:\\OneDrive\\RealTimeObjectDetection\\tensor\\lib\\site-packages\\tensorflow_core\\python\\lib\\io\\file_io.py\", line 84, in _preread_check\n",
      "    compat.as_bytes(self.__name), 1024 * 512)\n",
      "  File \"D:\\OneDrive\\RealTimeObjectDetection\\tensor\\lib\\site-packages\\tensorflow_core\\python\\util\\compat.py\", line 71, in as_bytes\n",
      "    (bytes_or_text,))\n",
      "TypeError: Expected binary or unicode string, got item {\n",
      "  name: \"\\340\\246\\271\\340\\247\\215\\340\\246\\257\\340\\246\\276\\340\\246\\262\\340\\247\\213\"\n",
      "  id: 1\n",
      "}\n",
      "item {\n",
      "  name: \"\\340\\246\\250\\340\\246\\276\"\n",
      "  id: 2\n",
      "}\n",
      "item {\n",
      "  name: \"\\340\\246\\271\\340\\247\\201\\340\\246\\256\"\n",
      "  id: 3\n",
      "}\n",
      "item {\n",
      "  name: \"\\340\\246\\247\\340\\246\\250\\340\\247\\215\\340\\246\\257\\340\\246\\254\\340\\246\\276\\340\\246\\246\"\n",
      "  id: 4\n",
      "}\n",
      "item {\n",
      "  name: \"\\340\\246\\206\\340\\246\\256\\340\\246\\277 \\340\\246\\244\\340\\247\\213\\340\\246\\256\\340\\246\\276\\340\\247\\237 \\340\\246\\255\\340\\246\\276\\340\\246\\262\\340\\247\\213\\340\\246\\254\\340\\246\\276\\340\\246\\270\\340\\246\\277\"\n",
      "  id: 5\n",
      "}\n",
      "\n",
      "Traceback (most recent call last):\n",
      "  File \"Tensorflow/scripts/generate_tfrecord.py\", line 62, in <module>\n",
      "    label_map_dict = label_map_util.get_label_map_dict(label_map)\n",
      "  File \"D:\\OneDrive\\RealTimeObjectDetection\\tensor\\lib\\site-packages\\object_detection\\utils\\label_map_util.py\", line 164, in get_label_map_dict\n",
      "    label_map = load_labelmap(label_map_path)\n",
      "  File \"D:\\OneDrive\\RealTimeObjectDetection\\tensor\\lib\\site-packages\\object_detection\\utils\\label_map_util.py\", line 133, in load_labelmap\n",
      "    label_map_string = fid.read()\n",
      "  File \"D:\\OneDrive\\RealTimeObjectDetection\\tensor\\lib\\site-packages\\tensorflow_core\\python\\lib\\io\\file_io.py\", line 122, in read\n",
      "    self._preread_check()\n",
      "  File \"D:\\OneDrive\\RealTimeObjectDetection\\tensor\\lib\\site-packages\\tensorflow_core\\python\\lib\\io\\file_io.py\", line 84, in _preread_check\n",
      "    compat.as_bytes(self.__name), 1024 * 512)\n",
      "  File \"D:\\OneDrive\\RealTimeObjectDetection\\tensor\\lib\\site-packages\\tensorflow_core\\python\\util\\compat.py\", line 71, in as_bytes\n",
      "    (bytes_or_text,))\n",
      "TypeError: Expected binary or unicode string, got item {\n",
      "  name: \"\\340\\246\\271\\340\\247\\215\\340\\246\\257\\340\\246\\276\\340\\246\\262\\340\\247\\213\"\n",
      "  id: 1\n",
      "}\n",
      "item {\n",
      "  name: \"\\340\\246\\250\\340\\246\\276\"\n",
      "  id: 2\n",
      "}\n",
      "item {\n",
      "  name: \"\\340\\246\\271\\340\\247\\201\\340\\246\\256\"\n",
      "  id: 3\n",
      "}\n",
      "item {\n",
      "  name: \"\\340\\246\\247\\340\\246\\250\\340\\247\\215\\340\\246\\257\\340\\246\\254\\340\\246\\276\\340\\246\\246\"\n",
      "  id: 4\n",
      "}\n",
      "item {\n",
      "  name: \"\\340\\246\\206\\340\\246\\256\\340\\246\\277 \\340\\246\\244\\340\\247\\213\\340\\246\\256\\340\\246\\276\\340\\247\\237 \\340\\246\\255\\340\\246\\276\\340\\246\\262\\340\\247\\213\\340\\246\\254\\340\\246\\276\\340\\246\\270\\340\\246\\277\"\n",
      "  id: 5\n",
      "}\n",
      "\n"
     ]
    }
   ],
   "source": [
    "!python {SCRIPTS_PATH + '/generate_tfrecord.py'} -x {IMAGE_PATH + '/train'} -l {ANNOTATION_PATH + '/label_map.pbtxt'} -o {ANNOTATION_PATH + '/train.record'}\n",
    "!python {SCRIPTS_PATH + '/generate_tfrecord.py'} -x{IMAGE_PATH + '/test'} -l {ANNOTATION_PATH + '/label_map.pbtxt'} -o {ANNOTATION_PATH + '/test.record'}"
   ]
  },
  {
   "cell_type": "markdown",
   "metadata": {},
   "source": [
    "# 3. Download TF Models Pretrained Models from Tensorflow Model Zoo"
   ]
  },
  {
   "cell_type": "code",
   "execution_count": 9,
   "metadata": {},
   "outputs": [
    {
     "name": "stderr",
     "output_type": "stream",
     "text": [
      "fatal: destination path 'models' already exists and is not an empty directory.\n"
     ]
    }
   ],
   "source": [
    "!cd Tensorflow && git clone https://github.com/tensorflow/models"
   ]
  },
  {
   "cell_type": "code",
   "execution_count": 6,
   "metadata": {},
   "outputs": [],
   "source": [
    "#wget.download('http://download.tensorflow.org/models/object_detection/tf2/20200711/ssd_mobilenet_v2_fpnlite_320x320_coco17_tpu-8.tar.gz')\n",
    "#!mv ssd_mobilenet_v2_fpnlite_320x320_coco17_tpu-8.tar.gz {PRETRAINED_MODEL_PATH}\n",
    "#!cd {PRETRAINED_MODEL_PATH} && tar -zxvf ssd_mobilenet_v2_fpnlite_320x320_coco17_tpu-8.tar.gz"
   ]
  },
  {
   "cell_type": "markdown",
   "metadata": {},
   "source": [
    "# 4. Copy Model Config to Training Folder"
   ]
  },
  {
   "cell_type": "code",
   "execution_count": 13,
   "metadata": {},
   "outputs": [],
   "source": [
    "CUSTOM_MODEL_NAME = 'my_ssd_mobnet' "
   ]
  },
  {
   "cell_type": "code",
   "execution_count": 14,
   "metadata": {},
   "outputs": [
    {
     "name": "stderr",
     "output_type": "stream",
     "text": [
      "A subdirectory or file Tensorflow\\workspace\\models\\my_ssd_mobnet already exists.\n"
     ]
    }
   ],
   "source": [
    "!mkdir {'Tensorflow\\workspace\\models\\\\'+CUSTOM_MODEL_NAME}\n",
    "!cp {PRETRAINED_MODEL_PATH+'/ssd_mobilenet_v2_fpnlite_320x320_coco17_tpu-8/pipeline.config'} {MODEL_PATH+'/'+CUSTOM_MODEL_NAME}"
   ]
  },
  {
   "cell_type": "markdown",
   "metadata": {},
   "source": [
    "# 5. Update Config For Transfer Learning"
   ]
  },
  {
   "cell_type": "code",
   "execution_count": null,
   "metadata": {},
   "outputs": [
    {
     "name": "stderr",
     "output_type": "stream",
     "text": [
      "ERROR:root:Internal Python error in the inspect module.\n",
      "Below is the traceback from this internal error.\n",
      "\n",
      "ERROR:root:Internal Python error in the inspect module.\n",
      "Below is the traceback from this internal error.\n",
      "\n",
      "ERROR:root:Internal Python error in the inspect module.\n",
      "Below is the traceback from this internal error.\n",
      "\n"
     ]
    },
    {
     "name": "stdout",
     "output_type": "stream",
     "text": [
      "Traceback (most recent call last):\n",
      "  File \"d:\\onedrive\\realtimeobjectdetection\\tensor\\lib\\site-packages\\IPython\\core\\interactiveshell.py\", line 3553, in run_code\n",
      "    exec(code_obj, self.user_global_ns, self.user_ns)\n",
      "  File \"C:\\Users\\HP\\AppData\\Local\\Temp\\ipykernel_9188\\880287751.py\", line 2, in <module>\n",
      "    from object_detection.utils import config_util\n",
      "  File \"d:\\onedrive\\realtimeobjectdetection\\tensor\\lib\\site-packages\\object_detection\\utils\\config_util.py\", line 22, in <module>\n",
      "    from tensorflow.python.lib.io import file_io\n",
      "  File \"d:\\onedrive\\realtimeobjectdetection\\tensor\\lib\\site-packages\\tensorflow_core\\python\\lib\\io\\file_io.py\", line 31, in <module>\n",
      "    from tensorflow.python.framework import c_api_util\n",
      "  File \"d:\\onedrive\\realtimeobjectdetection\\tensor\\lib\\site-packages\\tensorflow_core\\python\\framework\\c_api_util.py\", line 22, in <module>\n",
      "    from tensorflow.core.framework import api_def_pb2\n",
      "  File \"d:\\onedrive\\realtimeobjectdetection\\tensor\\lib\\site-packages\\tensorflow_core\\core\\framework\\api_def_pb2.py\", line 16, in <module>\n",
      "    from tensorflow.core.framework import attr_value_pb2 as tensorflow_dot_core_dot_framework_dot_attr__value__pb2\n",
      "  File \"d:\\onedrive\\realtimeobjectdetection\\tensor\\lib\\site-packages\\tensorflow_core\\core\\framework\\attr_value_pb2.py\", line 16, in <module>\n",
      "    from tensorflow.core.framework import tensor_pb2 as tensorflow_dot_core_dot_framework_dot_tensor__pb2\n",
      "  File \"d:\\onedrive\\realtimeobjectdetection\\tensor\\lib\\site-packages\\tensorflow_core\\core\\framework\\tensor_pb2.py\", line 16, in <module>\n",
      "    from tensorflow.core.framework import resource_handle_pb2 as tensorflow_dot_core_dot_framework_dot_resource__handle__pb2\n",
      "  File \"d:\\onedrive\\realtimeobjectdetection\\tensor\\lib\\site-packages\\tensorflow_core\\core\\framework\\resource_handle_pb2.py\", line 16, in <module>\n",
      "    from tensorflow.core.framework import tensor_shape_pb2 as tensorflow_dot_core_dot_framework_dot_tensor__shape__pb2\n",
      "  File \"d:\\onedrive\\realtimeobjectdetection\\tensor\\lib\\site-packages\\tensorflow_core\\core\\framework\\tensor_shape_pb2.py\", line 42, in <module>\n",
      "    serialized_options=None, file=DESCRIPTOR),\n",
      "  File \"d:\\onedrive\\realtimeobjectdetection\\tensor\\lib\\site-packages\\google\\protobuf\\descriptor.py\", line 560, in __new__\n",
      "    return _message.default_pool.FindFieldByName(full_name)\n",
      "TypeError: Descriptors cannot not be created directly.\n",
      "If this call came from a _pb2.py file, your generated code is out of date and must be regenerated with protoc >= 3.19.0.\n",
      "If you cannot immediately regenerate your protos, some other possible workarounds are:\n",
      " 1. Downgrade the protobuf package to 3.20.x or lower.\n",
      " 2. Set PROTOCOL_BUFFERS_PYTHON_IMPLEMENTATION=python (but this will use pure-Python parsing and will be much slower).\n",
      "\n",
      "More information: https://developers.google.com/protocol-buffers/docs/news/2022-05-06#python-updates\n",
      "\n",
      "During handling of the above exception, another exception occurred:\n",
      "\n",
      "Traceback (most recent call last):\n",
      "  File \"d:\\onedrive\\realtimeobjectdetection\\tensor\\lib\\site-packages\\IPython\\core\\interactiveshell.py\", line 2099, in showtraceback\n",
      "    stb = value._render_traceback_()\n",
      "AttributeError: 'TypeError' object has no attribute '_render_traceback_'\n",
      "\n",
      "During handling of the above exception, another exception occurred:\n",
      "\n",
      "Traceback (most recent call last):\n",
      "  File \"d:\\onedrive\\realtimeobjectdetection\\tensor\\lib\\site-packages\\IPython\\core\\ultratb.py\", line 1101, in get_records\n",
      "    return _fixed_getinnerframes(etb, number_of_lines_of_context, tb_offset)\n",
      "  File \"d:\\onedrive\\realtimeobjectdetection\\tensor\\lib\\site-packages\\IPython\\core\\ultratb.py\", line 248, in wrapped\n",
      "    return f(*args, **kwargs)\n",
      "  File \"d:\\onedrive\\realtimeobjectdetection\\tensor\\lib\\site-packages\\IPython\\core\\ultratb.py\", line 281, in _fixed_getinnerframes\n",
      "    records = fix_frame_records_filenames(inspect.getinnerframes(etb, context))\n",
      "  File \"C:\\python\\python37\\lib\\inspect.py\", line 1502, in getinnerframes\n",
      "    frameinfo = (tb.tb_frame,) + getframeinfo(tb, context)\n",
      "  File \"C:\\python\\python37\\lib\\inspect.py\", line 1460, in getframeinfo\n",
      "    filename = getsourcefile(frame) or getfile(frame)\n",
      "  File \"C:\\python\\python37\\lib\\inspect.py\", line 696, in getsourcefile\n",
      "    if getattr(getmodule(object, filename), '__loader__', None) is not None:\n",
      "  File \"C:\\python\\python37\\lib\\inspect.py\", line 733, in getmodule\n",
      "    if ismodule(module) and hasattr(module, '__file__'):\n",
      "  File \"d:\\onedrive\\realtimeobjectdetection\\tensor\\lib\\site-packages\\tensorflow\\__init__.py\", line 50, in __getattr__\n",
      "    module = self._load()\n",
      "  File \"d:\\onedrive\\realtimeobjectdetection\\tensor\\lib\\site-packages\\tensorflow\\__init__.py\", line 44, in _load\n",
      "    module = _importlib.import_module(self.__name__)\n",
      "  File \"C:\\python\\python37\\lib\\importlib\\__init__.py\", line 127, in import_module\n",
      "    return _bootstrap._gcd_import(name[level:], package, level)\n",
      "  File \"<frozen importlib._bootstrap>\", line 1006, in _gcd_import\n",
      "  File \"<frozen importlib._bootstrap>\", line 983, in _find_and_load\n",
      "  File \"<frozen importlib._bootstrap>\", line 953, in _find_and_load_unlocked\n",
      "  File \"<frozen importlib._bootstrap>\", line 219, in _call_with_frames_removed\n",
      "  File \"<frozen importlib._bootstrap>\", line 1006, in _gcd_import\n",
      "  File \"<frozen importlib._bootstrap>\", line 983, in _find_and_load\n",
      "  File \"<frozen importlib._bootstrap>\", line 967, in _find_and_load_unlocked\n",
      "  File \"<frozen importlib._bootstrap>\", line 677, in _load_unlocked\n",
      "  File \"<frozen importlib._bootstrap_external>\", line 728, in exec_module\n",
      "  File \"<frozen importlib._bootstrap>\", line 219, in _call_with_frames_removed\n",
      "  File \"d:\\onedrive\\realtimeobjectdetection\\tensor\\lib\\site-packages\\tensorflow_core\\__init__.py\", line 33, in <module>\n",
      "    from tensorflow._api.v1 import audio\n",
      "  File \"d:\\onedrive\\realtimeobjectdetection\\tensor\\lib\\site-packages\\tensorflow_core\\_api\\v1\\audio\\__init__.py\", line 10, in <module>\n",
      "    from tensorflow.python.ops.gen_audio_ops import decode_wav\n",
      "  File \"d:\\onedrive\\realtimeobjectdetection\\tensor\\lib\\site-packages\\tensorflow_core\\python\\ops\\gen_audio_ops.py\", line 10, in <module>\n",
      "    from tensorflow.python.eager import context as _context\n",
      "  File \"d:\\onedrive\\realtimeobjectdetection\\tensor\\lib\\site-packages\\tensorflow_core\\python\\eager\\context.py\", line 29, in <module>\n",
      "    from tensorflow.core.protobuf import config_pb2\n",
      "  File \"d:\\onedrive\\realtimeobjectdetection\\tensor\\lib\\site-packages\\tensorflow_core\\core\\protobuf\\config_pb2.py\", line 16, in <module>\n",
      "    from tensorflow.core.framework import cost_graph_pb2 as tensorflow_dot_core_dot_framework_dot_cost__graph__pb2\n",
      "  File \"d:\\onedrive\\realtimeobjectdetection\\tensor\\lib\\site-packages\\tensorflow_core\\core\\framework\\cost_graph_pb2.py\", line 16, in <module>\n",
      "    from tensorflow.core.framework import tensor_shape_pb2 as tensorflow_dot_core_dot_framework_dot_tensor__shape__pb2\n",
      "  File \"d:\\onedrive\\realtimeobjectdetection\\tensor\\lib\\site-packages\\tensorflow_core\\core\\framework\\tensor_shape_pb2.py\", line 42, in <module>\n",
      "    serialized_options=None, file=DESCRIPTOR),\n",
      "  File \"d:\\onedrive\\realtimeobjectdetection\\tensor\\lib\\site-packages\\google\\protobuf\\descriptor.py\", line 560, in __new__\n",
      "    return _message.default_pool.FindFieldByName(full_name)\n",
      "TypeError: Descriptors cannot not be created directly.\n",
      "If this call came from a _pb2.py file, your generated code is out of date and must be regenerated with protoc >= 3.19.0.\n",
      "If you cannot immediately regenerate your protos, some other possible workarounds are:\n",
      " 1. Downgrade the protobuf package to 3.20.x or lower.\n",
      " 2. Set PROTOCOL_BUFFERS_PYTHON_IMPLEMENTATION=python (but this will use pure-Python parsing and will be much slower).\n",
      "\n",
      "More information: https://developers.google.com/protocol-buffers/docs/news/2022-05-06#python-updates\n",
      "ERROR! Session/line number was not unique in database. History logging moved to new session 67\n",
      "Traceback (most recent call last):\n",
      "  File \"d:\\onedrive\\realtimeobjectdetection\\tensor\\lib\\site-packages\\IPython\\core\\interactiveshell.py\", line 3553, in run_code\n",
      "    exec(code_obj, self.user_global_ns, self.user_ns)\n",
      "  File \"C:\\Users\\HP\\AppData\\Local\\Temp\\ipykernel_9188\\880287751.py\", line 2, in <module>\n",
      "    from object_detection.utils import config_util\n",
      "  File \"d:\\onedrive\\realtimeobjectdetection\\tensor\\lib\\site-packages\\object_detection\\utils\\config_util.py\", line 22, in <module>\n",
      "    from tensorflow.python.lib.io import file_io\n",
      "  File \"d:\\onedrive\\realtimeobjectdetection\\tensor\\lib\\site-packages\\tensorflow_core\\python\\lib\\io\\file_io.py\", line 31, in <module>\n",
      "    from tensorflow.python.framework import c_api_util\n",
      "  File \"d:\\onedrive\\realtimeobjectdetection\\tensor\\lib\\site-packages\\tensorflow_core\\python\\framework\\c_api_util.py\", line 22, in <module>\n",
      "    from tensorflow.core.framework import api_def_pb2\n",
      "  File \"d:\\onedrive\\realtimeobjectdetection\\tensor\\lib\\site-packages\\tensorflow_core\\core\\framework\\api_def_pb2.py\", line 16, in <module>\n",
      "    from tensorflow.core.framework import attr_value_pb2 as tensorflow_dot_core_dot_framework_dot_attr__value__pb2\n",
      "  File \"d:\\onedrive\\realtimeobjectdetection\\tensor\\lib\\site-packages\\tensorflow_core\\core\\framework\\attr_value_pb2.py\", line 16, in <module>\n",
      "    from tensorflow.core.framework import tensor_pb2 as tensorflow_dot_core_dot_framework_dot_tensor__pb2\n",
      "  File \"d:\\onedrive\\realtimeobjectdetection\\tensor\\lib\\site-packages\\tensorflow_core\\core\\framework\\tensor_pb2.py\", line 16, in <module>\n",
      "    from tensorflow.core.framework import resource_handle_pb2 as tensorflow_dot_core_dot_framework_dot_resource__handle__pb2\n",
      "  File \"d:\\onedrive\\realtimeobjectdetection\\tensor\\lib\\site-packages\\tensorflow_core\\core\\framework\\resource_handle_pb2.py\", line 16, in <module>\n",
      "    from tensorflow.core.framework import tensor_shape_pb2 as tensorflow_dot_core_dot_framework_dot_tensor__shape__pb2\n",
      "  File \"d:\\onedrive\\realtimeobjectdetection\\tensor\\lib\\site-packages\\tensorflow_core\\core\\framework\\tensor_shape_pb2.py\", line 42, in <module>\n",
      "    serialized_options=None, file=DESCRIPTOR),\n",
      "  File \"d:\\onedrive\\realtimeobjectdetection\\tensor\\lib\\site-packages\\google\\protobuf\\descriptor.py\", line 560, in __new__\n",
      "    return _message.default_pool.FindFieldByName(full_name)\n",
      "TypeError: Descriptors cannot not be created directly.\n",
      "If this call came from a _pb2.py file, your generated code is out of date and must be regenerated with protoc >= 3.19.0.\n",
      "If you cannot immediately regenerate your protos, some other possible workarounds are:\n",
      " 1. Downgrade the protobuf package to 3.20.x or lower.\n",
      " 2. Set PROTOCOL_BUFFERS_PYTHON_IMPLEMENTATION=python (but this will use pure-Python parsing and will be much slower).\n",
      "\n",
      "More information: https://developers.google.com/protocol-buffers/docs/news/2022-05-06#python-updates\n",
      "\n",
      "During handling of the above exception, another exception occurred:\n",
      "\n",
      "Traceback (most recent call last):\n",
      "  File \"d:\\onedrive\\realtimeobjectdetection\\tensor\\lib\\site-packages\\IPython\\core\\interactiveshell.py\", line 2099, in showtraceback\n",
      "    stb = value._render_traceback_()\n",
      "AttributeError: 'TypeError' object has no attribute '_render_traceback_'\n",
      "\n",
      "During handling of the above exception, another exception occurred:\n",
      "\n",
      "Traceback (most recent call last):\n",
      "  File \"d:\\onedrive\\realtimeobjectdetection\\tensor\\lib\\site-packages\\IPython\\core\\interactiveshell.py\", line 3473, in run_ast_nodes\n",
      "    if (await self.run_code(code, result,  async_=asy)):\n",
      "  File \"d:\\onedrive\\realtimeobjectdetection\\tensor\\lib\\site-packages\\IPython\\core\\interactiveshell.py\", line 3575, in run_code\n",
      "    self.showtraceback(running_compiled_code=True)\n",
      "  File \"d:\\onedrive\\realtimeobjectdetection\\tensor\\lib\\site-packages\\IPython\\core\\interactiveshell.py\", line 2102, in showtraceback\n",
      "    value, tb, tb_offset=tb_offset)\n",
      "  File \"d:\\onedrive\\realtimeobjectdetection\\tensor\\lib\\site-packages\\IPython\\core\\ultratb.py\", line 1368, in structured_traceback\n",
      "    self, etype, value, tb, tb_offset, number_of_lines_of_context)\n",
      "  File \"d:\\onedrive\\realtimeobjectdetection\\tensor\\lib\\site-packages\\IPython\\core\\ultratb.py\", line 1268, in structured_traceback\n",
      "    self, etype, value, tb, tb_offset, number_of_lines_of_context\n",
      "  File \"d:\\onedrive\\realtimeobjectdetection\\tensor\\lib\\site-packages\\IPython\\core\\ultratb.py\", line 1125, in structured_traceback\n",
      "    tb_offset)\n",
      "  File \"d:\\onedrive\\realtimeobjectdetection\\tensor\\lib\\site-packages\\IPython\\core\\ultratb.py\", line 1082, in format_exception_as_a_whole\n",
      "    last_unique, recursion_repeat = find_recursion(orig_etype, evalue, records)\n",
      "  File \"d:\\onedrive\\realtimeobjectdetection\\tensor\\lib\\site-packages\\IPython\\core\\ultratb.py\", line 382, in find_recursion\n",
      "    return len(records), 0\n",
      "TypeError: object of type 'NoneType' has no len()\n",
      "\n",
      "During handling of the above exception, another exception occurred:\n",
      "\n",
      "Traceback (most recent call last):\n",
      "  File \"d:\\onedrive\\realtimeobjectdetection\\tensor\\lib\\site-packages\\IPython\\core\\interactiveshell.py\", line 2099, in showtraceback\n",
      "    stb = value._render_traceback_()\n",
      "AttributeError: 'TypeError' object has no attribute '_render_traceback_'\n",
      "\n",
      "During handling of the above exception, another exception occurred:\n",
      "\n",
      "Traceback (most recent call last):\n",
      "  File \"d:\\onedrive\\realtimeobjectdetection\\tensor\\lib\\site-packages\\IPython\\core\\ultratb.py\", line 1101, in get_records\n",
      "    return _fixed_getinnerframes(etb, number_of_lines_of_context, tb_offset)\n",
      "  File \"d:\\onedrive\\realtimeobjectdetection\\tensor\\lib\\site-packages\\IPython\\core\\ultratb.py\", line 248, in wrapped\n",
      "    return f(*args, **kwargs)\n",
      "  File \"d:\\onedrive\\realtimeobjectdetection\\tensor\\lib\\site-packages\\IPython\\core\\ultratb.py\", line 281, in _fixed_getinnerframes\n",
      "    records = fix_frame_records_filenames(inspect.getinnerframes(etb, context))\n",
      "  File \"C:\\python\\python37\\lib\\inspect.py\", line 1502, in getinnerframes\n",
      "    frameinfo = (tb.tb_frame,) + getframeinfo(tb, context)\n",
      "  File \"C:\\python\\python37\\lib\\inspect.py\", line 1460, in getframeinfo\n",
      "    filename = getsourcefile(frame) or getfile(frame)\n",
      "  File \"C:\\python\\python37\\lib\\inspect.py\", line 696, in getsourcefile\n",
      "    if getattr(getmodule(object, filename), '__loader__', None) is not None:\n",
      "  File \"C:\\python\\python37\\lib\\inspect.py\", line 733, in getmodule\n",
      "    if ismodule(module) and hasattr(module, '__file__'):\n",
      "  File \"d:\\onedrive\\realtimeobjectdetection\\tensor\\lib\\site-packages\\tensorflow\\__init__.py\", line 50, in __getattr__\n",
      "    module = self._load()\n",
      "  File \"d:\\onedrive\\realtimeobjectdetection\\tensor\\lib\\site-packages\\tensorflow\\__init__.py\", line 44, in _load\n",
      "    module = _importlib.import_module(self.__name__)\n",
      "  File \"C:\\python\\python37\\lib\\importlib\\__init__.py\", line 127, in import_module\n",
      "    return _bootstrap._gcd_import(name[level:], package, level)\n",
      "  File \"<frozen importlib._bootstrap>\", line 1006, in _gcd_import\n",
      "  File \"<frozen importlib._bootstrap>\", line 983, in _find_and_load\n",
      "  File \"<frozen importlib._bootstrap>\", line 953, in _find_and_load_unlocked\n",
      "  File \"<frozen importlib._bootstrap>\", line 219, in _call_with_frames_removed\n",
      "  File \"<frozen importlib._bootstrap>\", line 1006, in _gcd_import\n",
      "  File \"<frozen importlib._bootstrap>\", line 983, in _find_and_load\n",
      "  File \"<frozen importlib._bootstrap>\", line 967, in _find_and_load_unlocked\n",
      "  File \"<frozen importlib._bootstrap>\", line 677, in _load_unlocked\n",
      "  File \"<frozen importlib._bootstrap_external>\", line 728, in exec_module\n",
      "  File \"<frozen importlib._bootstrap>\", line 219, in _call_with_frames_removed\n",
      "  File \"d:\\onedrive\\realtimeobjectdetection\\tensor\\lib\\site-packages\\tensorflow_core\\__init__.py\", line 33, in <module>\n",
      "    from tensorflow._api.v1 import audio\n",
      "  File \"d:\\onedrive\\realtimeobjectdetection\\tensor\\lib\\site-packages\\tensorflow_core\\_api\\v1\\audio\\__init__.py\", line 10, in <module>\n",
      "    from tensorflow.python.ops.gen_audio_ops import decode_wav\n",
      "  File \"d:\\onedrive\\realtimeobjectdetection\\tensor\\lib\\site-packages\\tensorflow_core\\python\\ops\\gen_audio_ops.py\", line 10, in <module>\n",
      "    from tensorflow.python.eager import context as _context\n",
      "  File \"d:\\onedrive\\realtimeobjectdetection\\tensor\\lib\\site-packages\\tensorflow_core\\python\\eager\\context.py\", line 29, in <module>\n",
      "    from tensorflow.core.protobuf import config_pb2\n",
      "  File \"d:\\onedrive\\realtimeobjectdetection\\tensor\\lib\\site-packages\\tensorflow_core\\core\\protobuf\\config_pb2.py\", line 16, in <module>\n",
      "    from tensorflow.core.framework import cost_graph_pb2 as tensorflow_dot_core_dot_framework_dot_cost__graph__pb2\n",
      "  File \"d:\\onedrive\\realtimeobjectdetection\\tensor\\lib\\site-packages\\tensorflow_core\\core\\framework\\cost_graph_pb2.py\", line 16, in <module>\n",
      "    from tensorflow.core.framework import tensor_shape_pb2 as tensorflow_dot_core_dot_framework_dot_tensor__shape__pb2\n",
      "  File \"d:\\onedrive\\realtimeobjectdetection\\tensor\\lib\\site-packages\\tensorflow_core\\core\\framework\\tensor_shape_pb2.py\", line 42, in <module>\n",
      "    serialized_options=None, file=DESCRIPTOR),\n",
      "  File \"d:\\onedrive\\realtimeobjectdetection\\tensor\\lib\\site-packages\\google\\protobuf\\descriptor.py\", line 560, in __new__\n",
      "    return _message.default_pool.FindFieldByName(full_name)\n",
      "TypeError: Descriptors cannot not be created directly.\n",
      "If this call came from a _pb2.py file, your generated code is out of date and must be regenerated with protoc >= 3.19.0.\n",
      "If you cannot immediately regenerate your protos, some other possible workarounds are:\n",
      " 1. Downgrade the protobuf package to 3.20.x or lower.\n",
      " 2. Set PROTOCOL_BUFFERS_PYTHON_IMPLEMENTATION=python (but this will use pure-Python parsing and will be much slower).\n",
      "\n",
      "More information: https://developers.google.com/protocol-buffers/docs/news/2022-05-06#python-updates\n",
      "Traceback (most recent call last):\n",
      "  File \"d:\\onedrive\\realtimeobjectdetection\\tensor\\lib\\site-packages\\IPython\\core\\interactiveshell.py\", line 3553, in run_code\n",
      "    exec(code_obj, self.user_global_ns, self.user_ns)\n",
      "  File \"C:\\Users\\HP\\AppData\\Local\\Temp\\ipykernel_9188\\880287751.py\", line 2, in <module>\n",
      "    from object_detection.utils import config_util\n",
      "  File \"d:\\onedrive\\realtimeobjectdetection\\tensor\\lib\\site-packages\\object_detection\\utils\\config_util.py\", line 22, in <module>\n",
      "    from tensorflow.python.lib.io import file_io\n",
      "  File \"d:\\onedrive\\realtimeobjectdetection\\tensor\\lib\\site-packages\\tensorflow_core\\python\\lib\\io\\file_io.py\", line 31, in <module>\n",
      "    from tensorflow.python.framework import c_api_util\n",
      "  File \"d:\\onedrive\\realtimeobjectdetection\\tensor\\lib\\site-packages\\tensorflow_core\\python\\framework\\c_api_util.py\", line 22, in <module>\n",
      "    from tensorflow.core.framework import api_def_pb2\n",
      "  File \"d:\\onedrive\\realtimeobjectdetection\\tensor\\lib\\site-packages\\tensorflow_core\\core\\framework\\api_def_pb2.py\", line 16, in <module>\n",
      "    from tensorflow.core.framework import attr_value_pb2 as tensorflow_dot_core_dot_framework_dot_attr__value__pb2\n",
      "  File \"d:\\onedrive\\realtimeobjectdetection\\tensor\\lib\\site-packages\\tensorflow_core\\core\\framework\\attr_value_pb2.py\", line 16, in <module>\n",
      "    from tensorflow.core.framework import tensor_pb2 as tensorflow_dot_core_dot_framework_dot_tensor__pb2\n",
      "  File \"d:\\onedrive\\realtimeobjectdetection\\tensor\\lib\\site-packages\\tensorflow_core\\core\\framework\\tensor_pb2.py\", line 16, in <module>\n",
      "    from tensorflow.core.framework import resource_handle_pb2 as tensorflow_dot_core_dot_framework_dot_resource__handle__pb2\n",
      "  File \"d:\\onedrive\\realtimeobjectdetection\\tensor\\lib\\site-packages\\tensorflow_core\\core\\framework\\resource_handle_pb2.py\", line 16, in <module>\n",
      "    from tensorflow.core.framework import tensor_shape_pb2 as tensorflow_dot_core_dot_framework_dot_tensor__shape__pb2\n",
      "  File \"d:\\onedrive\\realtimeobjectdetection\\tensor\\lib\\site-packages\\tensorflow_core\\core\\framework\\tensor_shape_pb2.py\", line 42, in <module>\n",
      "    serialized_options=None, file=DESCRIPTOR),\n",
      "  File \"d:\\onedrive\\realtimeobjectdetection\\tensor\\lib\\site-packages\\google\\protobuf\\descriptor.py\", line 560, in __new__\n",
      "    return _message.default_pool.FindFieldByName(full_name)\n",
      "TypeError: Descriptors cannot not be created directly.\n",
      "If this call came from a _pb2.py file, your generated code is out of date and must be regenerated with protoc >= 3.19.0.\n",
      "If you cannot immediately regenerate your protos, some other possible workarounds are:\n",
      " 1. Downgrade the protobuf package to 3.20.x or lower.\n",
      " 2. Set PROTOCOL_BUFFERS_PYTHON_IMPLEMENTATION=python (but this will use pure-Python parsing and will be much slower).\n",
      "\n",
      "More information: https://developers.google.com/protocol-buffers/docs/news/2022-05-06#python-updates\n",
      "\n",
      "During handling of the above exception, another exception occurred:\n",
      "\n",
      "Traceback (most recent call last):\n",
      "  File \"d:\\onedrive\\realtimeobjectdetection\\tensor\\lib\\site-packages\\IPython\\core\\interactiveshell.py\", line 2099, in showtraceback\n",
      "    stb = value._render_traceback_()\n",
      "AttributeError: 'TypeError' object has no attribute '_render_traceback_'\n",
      "\n",
      "During handling of the above exception, another exception occurred:\n",
      "\n",
      "Traceback (most recent call last):\n",
      "  File \"d:\\onedrive\\realtimeobjectdetection\\tensor\\lib\\site-packages\\IPython\\core\\interactiveshell.py\", line 3473, in run_ast_nodes\n",
      "    if (await self.run_code(code, result,  async_=asy)):\n",
      "  File \"d:\\onedrive\\realtimeobjectdetection\\tensor\\lib\\site-packages\\IPython\\core\\interactiveshell.py\", line 3575, in run_code\n",
      "    self.showtraceback(running_compiled_code=True)\n",
      "  File \"d:\\onedrive\\realtimeobjectdetection\\tensor\\lib\\site-packages\\IPython\\core\\interactiveshell.py\", line 2102, in showtraceback\n",
      "    value, tb, tb_offset=tb_offset)\n",
      "  File \"d:\\onedrive\\realtimeobjectdetection\\tensor\\lib\\site-packages\\IPython\\core\\ultratb.py\", line 1368, in structured_traceback\n",
      "    self, etype, value, tb, tb_offset, number_of_lines_of_context)\n",
      "  File \"d:\\onedrive\\realtimeobjectdetection\\tensor\\lib\\site-packages\\IPython\\core\\ultratb.py\", line 1268, in structured_traceback\n",
      "    self, etype, value, tb, tb_offset, number_of_lines_of_context\n",
      "  File \"d:\\onedrive\\realtimeobjectdetection\\tensor\\lib\\site-packages\\IPython\\core\\ultratb.py\", line 1125, in structured_traceback\n",
      "    tb_offset)\n",
      "  File \"d:\\onedrive\\realtimeobjectdetection\\tensor\\lib\\site-packages\\IPython\\core\\ultratb.py\", line 1082, in format_exception_as_a_whole\n",
      "    last_unique, recursion_repeat = find_recursion(orig_etype, evalue, records)\n",
      "  File \"d:\\onedrive\\realtimeobjectdetection\\tensor\\lib\\site-packages\\IPython\\core\\ultratb.py\", line 382, in find_recursion\n",
      "    return len(records), 0\n",
      "TypeError: object of type 'NoneType' has no len()\n",
      "\n",
      "During handling of the above exception, another exception occurred:\n",
      "\n",
      "Traceback (most recent call last):\n",
      "  File \"d:\\onedrive\\realtimeobjectdetection\\tensor\\lib\\site-packages\\IPython\\core\\interactiveshell.py\", line 2099, in showtraceback\n",
      "    stb = value._render_traceback_()\n",
      "AttributeError: 'TypeError' object has no attribute '_render_traceback_'\n",
      "\n",
      "During handling of the above exception, another exception occurred:\n",
      "\n",
      "Traceback (most recent call last):\n",
      "  File \"d:\\onedrive\\realtimeobjectdetection\\tensor\\lib\\site-packages\\IPython\\core\\interactiveshell.py\", line 3030, in _run_cell\n",
      "    return runner(coro)\n",
      "  File \"d:\\onedrive\\realtimeobjectdetection\\tensor\\lib\\site-packages\\IPython\\core\\async_helpers.py\", line 78, in _pseudo_sync_runner\n",
      "    coro.send(None)\n",
      "  File \"d:\\onedrive\\realtimeobjectdetection\\tensor\\lib\\site-packages\\IPython\\core\\interactiveshell.py\", line 3258, in run_cell_async\n",
      "    interactivity=interactivity, compiler=compiler, result=result)\n",
      "  File \"d:\\onedrive\\realtimeobjectdetection\\tensor\\lib\\site-packages\\IPython\\core\\interactiveshell.py\", line 3492, in run_ast_nodes\n",
      "    self.showtraceback()\n",
      "  File \"d:\\onedrive\\realtimeobjectdetection\\tensor\\lib\\site-packages\\IPython\\core\\interactiveshell.py\", line 2102, in showtraceback\n",
      "    value, tb, tb_offset=tb_offset)\n",
      "  File \"d:\\onedrive\\realtimeobjectdetection\\tensor\\lib\\site-packages\\IPython\\core\\ultratb.py\", line 1368, in structured_traceback\n",
      "    self, etype, value, tb, tb_offset, number_of_lines_of_context)\n",
      "  File \"d:\\onedrive\\realtimeobjectdetection\\tensor\\lib\\site-packages\\IPython\\core\\ultratb.py\", line 1268, in structured_traceback\n",
      "    self, etype, value, tb, tb_offset, number_of_lines_of_context\n",
      "  File \"d:\\onedrive\\realtimeobjectdetection\\tensor\\lib\\site-packages\\IPython\\core\\ultratb.py\", line 1143, in structured_traceback\n",
      "    chained_exceptions_tb_offset)\n",
      "  File \"d:\\onedrive\\realtimeobjectdetection\\tensor\\lib\\site-packages\\IPython\\core\\ultratb.py\", line 1082, in format_exception_as_a_whole\n",
      "    last_unique, recursion_repeat = find_recursion(orig_etype, evalue, records)\n",
      "  File \"d:\\onedrive\\realtimeobjectdetection\\tensor\\lib\\site-packages\\IPython\\core\\ultratb.py\", line 382, in find_recursion\n",
      "    return len(records), 0\n",
      "TypeError: object of type 'NoneType' has no len()\n",
      "\n",
      "During handling of the above exception, another exception occurred:\n",
      "\n",
      "Traceback (most recent call last):\n",
      "  File \"d:\\onedrive\\realtimeobjectdetection\\tensor\\lib\\site-packages\\IPython\\core\\interactiveshell.py\", line 2099, in showtraceback\n",
      "    stb = value._render_traceback_()\n",
      "AttributeError: 'TypeError' object has no attribute '_render_traceback_'\n",
      "\n",
      "During handling of the above exception, another exception occurred:\n",
      "\n",
      "Traceback (most recent call last):\n",
      "  File \"d:\\onedrive\\realtimeobjectdetection\\tensor\\lib\\site-packages\\IPython\\core\\ultratb.py\", line 1101, in get_records\n",
      "    return _fixed_getinnerframes(etb, number_of_lines_of_context, tb_offset)\n",
      "  File \"d:\\onedrive\\realtimeobjectdetection\\tensor\\lib\\site-packages\\IPython\\core\\ultratb.py\", line 248, in wrapped\n",
      "    return f(*args, **kwargs)\n",
      "  File \"d:\\onedrive\\realtimeobjectdetection\\tensor\\lib\\site-packages\\IPython\\core\\ultratb.py\", line 281, in _fixed_getinnerframes\n",
      "    records = fix_frame_records_filenames(inspect.getinnerframes(etb, context))\n",
      "  File \"C:\\python\\python37\\lib\\inspect.py\", line 1502, in getinnerframes\n",
      "    frameinfo = (tb.tb_frame,) + getframeinfo(tb, context)\n",
      "  File \"C:\\python\\python37\\lib\\inspect.py\", line 1460, in getframeinfo\n",
      "    filename = getsourcefile(frame) or getfile(frame)\n",
      "  File \"C:\\python\\python37\\lib\\inspect.py\", line 696, in getsourcefile\n",
      "    if getattr(getmodule(object, filename), '__loader__', None) is not None:\n",
      "  File \"C:\\python\\python37\\lib\\inspect.py\", line 733, in getmodule\n",
      "    if ismodule(module) and hasattr(module, '__file__'):\n",
      "  File \"d:\\onedrive\\realtimeobjectdetection\\tensor\\lib\\site-packages\\tensorflow\\__init__.py\", line 50, in __getattr__\n",
      "    module = self._load()\n",
      "  File \"d:\\onedrive\\realtimeobjectdetection\\tensor\\lib\\site-packages\\tensorflow\\__init__.py\", line 44, in _load\n",
      "    module = _importlib.import_module(self.__name__)\n",
      "  File \"C:\\python\\python37\\lib\\importlib\\__init__.py\", line 127, in import_module\n",
      "    return _bootstrap._gcd_import(name[level:], package, level)\n",
      "  File \"<frozen importlib._bootstrap>\", line 1006, in _gcd_import\n",
      "  File \"<frozen importlib._bootstrap>\", line 983, in _find_and_load\n",
      "  File \"<frozen importlib._bootstrap>\", line 953, in _find_and_load_unlocked\n",
      "  File \"<frozen importlib._bootstrap>\", line 219, in _call_with_frames_removed\n",
      "  File \"<frozen importlib._bootstrap>\", line 1006, in _gcd_import\n",
      "  File \"<frozen importlib._bootstrap>\", line 983, in _find_and_load\n",
      "  File \"<frozen importlib._bootstrap>\", line 967, in _find_and_load_unlocked\n",
      "  File \"<frozen importlib._bootstrap>\", line 677, in _load_unlocked\n",
      "  File \"<frozen importlib._bootstrap_external>\", line 728, in exec_module\n",
      "  File \"<frozen importlib._bootstrap>\", line 219, in _call_with_frames_removed\n",
      "  File \"d:\\onedrive\\realtimeobjectdetection\\tensor\\lib\\site-packages\\tensorflow_core\\__init__.py\", line 33, in <module>\n",
      "    from tensorflow._api.v1 import audio\n",
      "  File \"d:\\onedrive\\realtimeobjectdetection\\tensor\\lib\\site-packages\\tensorflow_core\\_api\\v1\\audio\\__init__.py\", line 10, in <module>\n",
      "    from tensorflow.python.ops.gen_audio_ops import decode_wav\n",
      "  File \"d:\\onedrive\\realtimeobjectdetection\\tensor\\lib\\site-packages\\tensorflow_core\\python\\ops\\gen_audio_ops.py\", line 10, in <module>\n",
      "    from tensorflow.python.eager import context as _context\n",
      "  File \"d:\\onedrive\\realtimeobjectdetection\\tensor\\lib\\site-packages\\tensorflow_core\\python\\eager\\context.py\", line 29, in <module>\n",
      "    from tensorflow.core.protobuf import config_pb2\n",
      "  File \"d:\\onedrive\\realtimeobjectdetection\\tensor\\lib\\site-packages\\tensorflow_core\\core\\protobuf\\config_pb2.py\", line 16, in <module>\n",
      "    from tensorflow.core.framework import cost_graph_pb2 as tensorflow_dot_core_dot_framework_dot_cost__graph__pb2\n",
      "  File \"d:\\onedrive\\realtimeobjectdetection\\tensor\\lib\\site-packages\\tensorflow_core\\core\\framework\\cost_graph_pb2.py\", line 16, in <module>\n",
      "    from tensorflow.core.framework import tensor_shape_pb2 as tensorflow_dot_core_dot_framework_dot_tensor__shape__pb2\n",
      "  File \"d:\\onedrive\\realtimeobjectdetection\\tensor\\lib\\site-packages\\tensorflow_core\\core\\framework\\tensor_shape_pb2.py\", line 42, in <module>\n",
      "    serialized_options=None, file=DESCRIPTOR),\n",
      "  File \"d:\\onedrive\\realtimeobjectdetection\\tensor\\lib\\site-packages\\google\\protobuf\\descriptor.py\", line 560, in __new__\n",
      "    return _message.default_pool.FindFieldByName(full_name)\n",
      "TypeError: Descriptors cannot not be created directly.\n",
      "If this call came from a _pb2.py file, your generated code is out of date and must be regenerated with protoc >= 3.19.0.\n",
      "If you cannot immediately regenerate your protos, some other possible workarounds are:\n",
      " 1. Downgrade the protobuf package to 3.20.x or lower.\n",
      " 2. Set PROTOCOL_BUFFERS_PYTHON_IMPLEMENTATION=python (but this will use pure-Python parsing and will be much slower).\n",
      "\n",
      "More information: https://developers.google.com/protocol-buffers/docs/news/2022-05-06#python-updates\n"
     ]
    }
   ],
   "source": [
    "import tensorflow as tf\n",
    "from object_detection.utils import config_util\n",
    "from object_detection.protos import pipeline_pb2\n",
    "from google.protobuf import text_format"
   ]
  },
  {
   "cell_type": "code",
   "execution_count": 9,
   "metadata": {},
   "outputs": [
    {
     "data": {
      "text/plain": [
       "'2.9.1'"
      ]
     },
     "execution_count": 9,
     "metadata": {},
     "output_type": "execute_result"
    }
   ],
   "source": [
    "tf.__version__"
   ]
  },
  {
   "cell_type": "code",
   "execution_count": 17,
   "metadata": {},
   "outputs": [
    {
     "name": "stdout",
     "output_type": "stream",
     "text": [
      "ERROR! Session/line number was not unique in database. History logging moved to new session 72\n"
     ]
    }
   ],
   "source": [
    "CONFIG_PATH = MODEL_PATH+'/'+CUSTOM_MODEL_NAME+'/pipeline.config'"
   ]
  },
  {
   "cell_type": "code",
   "execution_count": null,
   "metadata": {},
   "outputs": [
    {
     "name": "stderr",
     "output_type": "stream",
     "text": [
      "ERROR:root:Internal Python error in the inspect module.\n",
      "Below is the traceback from this internal error.\n",
      "\n",
      "ERROR:root:Internal Python error in the inspect module.\n",
      "Below is the traceback from this internal error.\n",
      "\n",
      "ERROR:root:Internal Python error in the inspect module.\n",
      "Below is the traceback from this internal error.\n",
      "\n"
     ]
    },
    {
     "name": "stdout",
     "output_type": "stream",
     "text": [
      "Traceback (most recent call last):\n",
      "  File \"d:\\onedrive\\realtimeobjectdetection\\tensor\\lib\\site-packages\\IPython\\core\\interactiveshell.py\", line 3553, in run_code\n",
      "    exec(code_obj, self.user_global_ns, self.user_ns)\n",
      "  File \"C:\\Users\\HP\\AppData\\Local\\Temp\\ipykernel_9188\\2792951555.py\", line 1, in <module>\n",
      "    config = config_util.get_configs_from_pipeline_file(CONFIG_PATH)\n",
      "NameError: name 'config_util' is not defined\n",
      "\n",
      "During handling of the above exception, another exception occurred:\n",
      "\n",
      "Traceback (most recent call last):\n",
      "  File \"d:\\onedrive\\realtimeobjectdetection\\tensor\\lib\\site-packages\\IPython\\core\\interactiveshell.py\", line 2099, in showtraceback\n",
      "    stb = value._render_traceback_()\n",
      "AttributeError: 'NameError' object has no attribute '_render_traceback_'\n",
      "\n",
      "During handling of the above exception, another exception occurred:\n",
      "\n",
      "Traceback (most recent call last):\n",
      "  File \"d:\\onedrive\\realtimeobjectdetection\\tensor\\lib\\site-packages\\IPython\\core\\ultratb.py\", line 1101, in get_records\n",
      "    return _fixed_getinnerframes(etb, number_of_lines_of_context, tb_offset)\n",
      "  File \"d:\\onedrive\\realtimeobjectdetection\\tensor\\lib\\site-packages\\IPython\\core\\ultratb.py\", line 248, in wrapped\n",
      "    return f(*args, **kwargs)\n",
      "  File \"d:\\onedrive\\realtimeobjectdetection\\tensor\\lib\\site-packages\\IPython\\core\\ultratb.py\", line 281, in _fixed_getinnerframes\n",
      "    records = fix_frame_records_filenames(inspect.getinnerframes(etb, context))\n",
      "  File \"C:\\python\\python37\\lib\\inspect.py\", line 1502, in getinnerframes\n",
      "    frameinfo = (tb.tb_frame,) + getframeinfo(tb, context)\n",
      "  File \"C:\\python\\python37\\lib\\inspect.py\", line 1460, in getframeinfo\n",
      "    filename = getsourcefile(frame) or getfile(frame)\n",
      "  File \"C:\\python\\python37\\lib\\inspect.py\", line 696, in getsourcefile\n",
      "    if getattr(getmodule(object, filename), '__loader__', None) is not None:\n",
      "  File \"C:\\python\\python37\\lib\\inspect.py\", line 733, in getmodule\n",
      "    if ismodule(module) and hasattr(module, '__file__'):\n",
      "  File \"d:\\onedrive\\realtimeobjectdetection\\tensor\\lib\\site-packages\\tensorflow\\__init__.py\", line 50, in __getattr__\n",
      "    module = self._load()\n",
      "  File \"d:\\onedrive\\realtimeobjectdetection\\tensor\\lib\\site-packages\\tensorflow\\__init__.py\", line 44, in _load\n",
      "    module = _importlib.import_module(self.__name__)\n",
      "  File \"C:\\python\\python37\\lib\\importlib\\__init__.py\", line 127, in import_module\n",
      "    return _bootstrap._gcd_import(name[level:], package, level)\n",
      "  File \"<frozen importlib._bootstrap>\", line 1006, in _gcd_import\n",
      "  File \"<frozen importlib._bootstrap>\", line 983, in _find_and_load\n",
      "  File \"<frozen importlib._bootstrap>\", line 953, in _find_and_load_unlocked\n",
      "  File \"<frozen importlib._bootstrap>\", line 219, in _call_with_frames_removed\n",
      "  File \"<frozen importlib._bootstrap>\", line 1006, in _gcd_import\n",
      "  File \"<frozen importlib._bootstrap>\", line 983, in _find_and_load\n",
      "  File \"<frozen importlib._bootstrap>\", line 967, in _find_and_load_unlocked\n",
      "  File \"<frozen importlib._bootstrap>\", line 677, in _load_unlocked\n",
      "  File \"<frozen importlib._bootstrap_external>\", line 728, in exec_module\n",
      "  File \"<frozen importlib._bootstrap>\", line 219, in _call_with_frames_removed\n",
      "  File \"d:\\onedrive\\realtimeobjectdetection\\tensor\\lib\\site-packages\\tensorflow_core\\__init__.py\", line 33, in <module>\n",
      "    from tensorflow._api.v1 import audio\n",
      "  File \"d:\\onedrive\\realtimeobjectdetection\\tensor\\lib\\site-packages\\tensorflow_core\\_api\\v1\\audio\\__init__.py\", line 10, in <module>\n",
      "    from tensorflow.python.ops.gen_audio_ops import decode_wav\n",
      "  File \"d:\\onedrive\\realtimeobjectdetection\\tensor\\lib\\site-packages\\tensorflow_core\\python\\ops\\gen_audio_ops.py\", line 10, in <module>\n",
      "    from tensorflow.python.eager import context as _context\n",
      "  File \"d:\\onedrive\\realtimeobjectdetection\\tensor\\lib\\site-packages\\tensorflow_core\\python\\eager\\context.py\", line 29, in <module>\n",
      "    from tensorflow.core.protobuf import config_pb2\n",
      "  File \"d:\\onedrive\\realtimeobjectdetection\\tensor\\lib\\site-packages\\tensorflow_core\\core\\protobuf\\config_pb2.py\", line 16, in <module>\n",
      "    from tensorflow.core.framework import cost_graph_pb2 as tensorflow_dot_core_dot_framework_dot_cost__graph__pb2\n",
      "  File \"d:\\onedrive\\realtimeobjectdetection\\tensor\\lib\\site-packages\\tensorflow_core\\core\\framework\\cost_graph_pb2.py\", line 16, in <module>\n",
      "    from tensorflow.core.framework import tensor_shape_pb2 as tensorflow_dot_core_dot_framework_dot_tensor__shape__pb2\n",
      "  File \"d:\\onedrive\\realtimeobjectdetection\\tensor\\lib\\site-packages\\tensorflow_core\\core\\framework\\tensor_shape_pb2.py\", line 42, in <module>\n",
      "    serialized_options=None, file=DESCRIPTOR),\n",
      "  File \"d:\\onedrive\\realtimeobjectdetection\\tensor\\lib\\site-packages\\google\\protobuf\\descriptor.py\", line 560, in __new__\n",
      "    return _message.default_pool.FindFieldByName(full_name)\n",
      "TypeError: Descriptors cannot not be created directly.\n",
      "If this call came from a _pb2.py file, your generated code is out of date and must be regenerated with protoc >= 3.19.0.\n",
      "If you cannot immediately regenerate your protos, some other possible workarounds are:\n",
      " 1. Downgrade the protobuf package to 3.20.x or lower.\n",
      " 2. Set PROTOCOL_BUFFERS_PYTHON_IMPLEMENTATION=python (but this will use pure-Python parsing and will be much slower).\n",
      "\n",
      "More information: https://developers.google.com/protocol-buffers/docs/news/2022-05-06#python-updates\n",
      "Traceback (most recent call last):\n",
      "  File \"d:\\onedrive\\realtimeobjectdetection\\tensor\\lib\\site-packages\\IPython\\core\\interactiveshell.py\", line 3553, in run_code\n",
      "    exec(code_obj, self.user_global_ns, self.user_ns)\n",
      "  File \"C:\\Users\\HP\\AppData\\Local\\Temp\\ipykernel_9188\\2792951555.py\", line 1, in <module>\n",
      "    config = config_util.get_configs_from_pipeline_file(CONFIG_PATH)\n",
      "NameError: name 'config_util' is not defined\n",
      "\n",
      "During handling of the above exception, another exception occurred:\n",
      "\n",
      "Traceback (most recent call last):\n",
      "  File \"d:\\onedrive\\realtimeobjectdetection\\tensor\\lib\\site-packages\\IPython\\core\\interactiveshell.py\", line 2099, in showtraceback\n",
      "    stb = value._render_traceback_()\n",
      "AttributeError: 'NameError' object has no attribute '_render_traceback_'\n",
      "\n",
      "During handling of the above exception, another exception occurred:\n",
      "\n",
      "Traceback (most recent call last):\n",
      "  File \"d:\\onedrive\\realtimeobjectdetection\\tensor\\lib\\site-packages\\IPython\\core\\interactiveshell.py\", line 3473, in run_ast_nodes\n",
      "    if (await self.run_code(code, result,  async_=asy)):\n",
      "  File \"d:\\onedrive\\realtimeobjectdetection\\tensor\\lib\\site-packages\\IPython\\core\\interactiveshell.py\", line 3575, in run_code\n",
      "    self.showtraceback(running_compiled_code=True)\n",
      "  File \"d:\\onedrive\\realtimeobjectdetection\\tensor\\lib\\site-packages\\IPython\\core\\interactiveshell.py\", line 2102, in showtraceback\n",
      "    value, tb, tb_offset=tb_offset)\n",
      "  File \"d:\\onedrive\\realtimeobjectdetection\\tensor\\lib\\site-packages\\IPython\\core\\ultratb.py\", line 1368, in structured_traceback\n",
      "    self, etype, value, tb, tb_offset, number_of_lines_of_context)\n",
      "  File \"d:\\onedrive\\realtimeobjectdetection\\tensor\\lib\\site-packages\\IPython\\core\\ultratb.py\", line 1268, in structured_traceback\n",
      "    self, etype, value, tb, tb_offset, number_of_lines_of_context\n",
      "  File \"d:\\onedrive\\realtimeobjectdetection\\tensor\\lib\\site-packages\\IPython\\core\\ultratb.py\", line 1125, in structured_traceback\n",
      "    tb_offset)\n",
      "  File \"d:\\onedrive\\realtimeobjectdetection\\tensor\\lib\\site-packages\\IPython\\core\\ultratb.py\", line 1082, in format_exception_as_a_whole\n",
      "    last_unique, recursion_repeat = find_recursion(orig_etype, evalue, records)\n",
      "  File \"d:\\onedrive\\realtimeobjectdetection\\tensor\\lib\\site-packages\\IPython\\core\\ultratb.py\", line 382, in find_recursion\n",
      "    return len(records), 0\n",
      "TypeError: object of type 'NoneType' has no len()\n",
      "\n",
      "During handling of the above exception, another exception occurred:\n",
      "\n",
      "Traceback (most recent call last):\n",
      "  File \"d:\\onedrive\\realtimeobjectdetection\\tensor\\lib\\site-packages\\IPython\\core\\interactiveshell.py\", line 2099, in showtraceback\n",
      "    stb = value._render_traceback_()\n",
      "AttributeError: 'TypeError' object has no attribute '_render_traceback_'\n",
      "\n",
      "During handling of the above exception, another exception occurred:\n",
      "\n",
      "Traceback (most recent call last):\n",
      "  File \"d:\\onedrive\\realtimeobjectdetection\\tensor\\lib\\site-packages\\IPython\\core\\ultratb.py\", line 1101, in get_records\n",
      "    return _fixed_getinnerframes(etb, number_of_lines_of_context, tb_offset)\n",
      "  File \"d:\\onedrive\\realtimeobjectdetection\\tensor\\lib\\site-packages\\IPython\\core\\ultratb.py\", line 248, in wrapped\n",
      "    return f(*args, **kwargs)\n",
      "  File \"d:\\onedrive\\realtimeobjectdetection\\tensor\\lib\\site-packages\\IPython\\core\\ultratb.py\", line 281, in _fixed_getinnerframes\n",
      "    records = fix_frame_records_filenames(inspect.getinnerframes(etb, context))\n",
      "  File \"C:\\python\\python37\\lib\\inspect.py\", line 1502, in getinnerframes\n",
      "    frameinfo = (tb.tb_frame,) + getframeinfo(tb, context)\n",
      "  File \"C:\\python\\python37\\lib\\inspect.py\", line 1460, in getframeinfo\n",
      "    filename = getsourcefile(frame) or getfile(frame)\n",
      "  File \"C:\\python\\python37\\lib\\inspect.py\", line 696, in getsourcefile\n",
      "    if getattr(getmodule(object, filename), '__loader__', None) is not None:\n",
      "  File \"C:\\python\\python37\\lib\\inspect.py\", line 733, in getmodule\n",
      "    if ismodule(module) and hasattr(module, '__file__'):\n",
      "  File \"d:\\onedrive\\realtimeobjectdetection\\tensor\\lib\\site-packages\\tensorflow\\__init__.py\", line 50, in __getattr__\n",
      "    module = self._load()\n",
      "  File \"d:\\onedrive\\realtimeobjectdetection\\tensor\\lib\\site-packages\\tensorflow\\__init__.py\", line 44, in _load\n",
      "    module = _importlib.import_module(self.__name__)\n",
      "  File \"C:\\python\\python37\\lib\\importlib\\__init__.py\", line 127, in import_module\n",
      "    return _bootstrap._gcd_import(name[level:], package, level)\n",
      "  File \"<frozen importlib._bootstrap>\", line 1006, in _gcd_import\n",
      "  File \"<frozen importlib._bootstrap>\", line 983, in _find_and_load\n",
      "  File \"<frozen importlib._bootstrap>\", line 953, in _find_and_load_unlocked\n",
      "  File \"<frozen importlib._bootstrap>\", line 219, in _call_with_frames_removed\n",
      "  File \"<frozen importlib._bootstrap>\", line 1006, in _gcd_import\n",
      "  File \"<frozen importlib._bootstrap>\", line 983, in _find_and_load\n",
      "  File \"<frozen importlib._bootstrap>\", line 967, in _find_and_load_unlocked\n",
      "  File \"<frozen importlib._bootstrap>\", line 677, in _load_unlocked\n",
      "  File \"<frozen importlib._bootstrap_external>\", line 728, in exec_module\n",
      "  File \"<frozen importlib._bootstrap>\", line 219, in _call_with_frames_removed\n",
      "  File \"d:\\onedrive\\realtimeobjectdetection\\tensor\\lib\\site-packages\\tensorflow_core\\__init__.py\", line 33, in <module>\n",
      "    from tensorflow._api.v1 import audio\n",
      "  File \"d:\\onedrive\\realtimeobjectdetection\\tensor\\lib\\site-packages\\tensorflow_core\\_api\\v1\\audio\\__init__.py\", line 10, in <module>\n",
      "    from tensorflow.python.ops.gen_audio_ops import decode_wav\n",
      "  File \"d:\\onedrive\\realtimeobjectdetection\\tensor\\lib\\site-packages\\tensorflow_core\\python\\ops\\gen_audio_ops.py\", line 10, in <module>\n",
      "    from tensorflow.python.eager import context as _context\n",
      "  File \"d:\\onedrive\\realtimeobjectdetection\\tensor\\lib\\site-packages\\tensorflow_core\\python\\eager\\context.py\", line 29, in <module>\n",
      "    from tensorflow.core.protobuf import config_pb2\n",
      "  File \"d:\\onedrive\\realtimeobjectdetection\\tensor\\lib\\site-packages\\tensorflow_core\\core\\protobuf\\config_pb2.py\", line 16, in <module>\n",
      "    from tensorflow.core.framework import cost_graph_pb2 as tensorflow_dot_core_dot_framework_dot_cost__graph__pb2\n",
      "  File \"d:\\onedrive\\realtimeobjectdetection\\tensor\\lib\\site-packages\\tensorflow_core\\core\\framework\\cost_graph_pb2.py\", line 16, in <module>\n",
      "    from tensorflow.core.framework import tensor_shape_pb2 as tensorflow_dot_core_dot_framework_dot_tensor__shape__pb2\n",
      "  File \"d:\\onedrive\\realtimeobjectdetection\\tensor\\lib\\site-packages\\tensorflow_core\\core\\framework\\tensor_shape_pb2.py\", line 42, in <module>\n",
      "    serialized_options=None, file=DESCRIPTOR),\n",
      "  File \"d:\\onedrive\\realtimeobjectdetection\\tensor\\lib\\site-packages\\google\\protobuf\\descriptor.py\", line 560, in __new__\n",
      "    return _message.default_pool.FindFieldByName(full_name)\n",
      "TypeError: Descriptors cannot not be created directly.\n",
      "If this call came from a _pb2.py file, your generated code is out of date and must be regenerated with protoc >= 3.19.0.\n",
      "If you cannot immediately regenerate your protos, some other possible workarounds are:\n",
      " 1. Downgrade the protobuf package to 3.20.x or lower.\n",
      " 2. Set PROTOCOL_BUFFERS_PYTHON_IMPLEMENTATION=python (but this will use pure-Python parsing and will be much slower).\n",
      "\n",
      "More information: https://developers.google.com/protocol-buffers/docs/news/2022-05-06#python-updates\n",
      "Traceback (most recent call last):\n",
      "  File \"d:\\onedrive\\realtimeobjectdetection\\tensor\\lib\\site-packages\\IPython\\core\\interactiveshell.py\", line 3553, in run_code\n",
      "    exec(code_obj, self.user_global_ns, self.user_ns)\n",
      "  File \"C:\\Users\\HP\\AppData\\Local\\Temp\\ipykernel_9188\\2792951555.py\", line 1, in <module>\n",
      "    config = config_util.get_configs_from_pipeline_file(CONFIG_PATH)\n",
      "NameError: name 'config_util' is not defined\n",
      "\n",
      "During handling of the above exception, another exception occurred:\n",
      "\n",
      "Traceback (most recent call last):\n",
      "  File \"d:\\onedrive\\realtimeobjectdetection\\tensor\\lib\\site-packages\\IPython\\core\\interactiveshell.py\", line 2099, in showtraceback\n",
      "    stb = value._render_traceback_()\n",
      "AttributeError: 'NameError' object has no attribute '_render_traceback_'\n",
      "\n",
      "During handling of the above exception, another exception occurred:\n",
      "\n",
      "Traceback (most recent call last):\n",
      "  File \"d:\\onedrive\\realtimeobjectdetection\\tensor\\lib\\site-packages\\IPython\\core\\interactiveshell.py\", line 3473, in run_ast_nodes\n",
      "    if (await self.run_code(code, result,  async_=asy)):\n",
      "  File \"d:\\onedrive\\realtimeobjectdetection\\tensor\\lib\\site-packages\\IPython\\core\\interactiveshell.py\", line 3575, in run_code\n",
      "    self.showtraceback(running_compiled_code=True)\n",
      "  File \"d:\\onedrive\\realtimeobjectdetection\\tensor\\lib\\site-packages\\IPython\\core\\interactiveshell.py\", line 2102, in showtraceback\n",
      "    value, tb, tb_offset=tb_offset)\n",
      "  File \"d:\\onedrive\\realtimeobjectdetection\\tensor\\lib\\site-packages\\IPython\\core\\ultratb.py\", line 1368, in structured_traceback\n",
      "    self, etype, value, tb, tb_offset, number_of_lines_of_context)\n",
      "  File \"d:\\onedrive\\realtimeobjectdetection\\tensor\\lib\\site-packages\\IPython\\core\\ultratb.py\", line 1268, in structured_traceback\n",
      "    self, etype, value, tb, tb_offset, number_of_lines_of_context\n",
      "  File \"d:\\onedrive\\realtimeobjectdetection\\tensor\\lib\\site-packages\\IPython\\core\\ultratb.py\", line 1125, in structured_traceback\n",
      "    tb_offset)\n",
      "  File \"d:\\onedrive\\realtimeobjectdetection\\tensor\\lib\\site-packages\\IPython\\core\\ultratb.py\", line 1082, in format_exception_as_a_whole\n",
      "    last_unique, recursion_repeat = find_recursion(orig_etype, evalue, records)\n",
      "  File \"d:\\onedrive\\realtimeobjectdetection\\tensor\\lib\\site-packages\\IPython\\core\\ultratb.py\", line 382, in find_recursion\n",
      "    return len(records), 0\n",
      "TypeError: object of type 'NoneType' has no len()\n",
      "\n",
      "During handling of the above exception, another exception occurred:\n",
      "\n",
      "Traceback (most recent call last):\n",
      "  File \"d:\\onedrive\\realtimeobjectdetection\\tensor\\lib\\site-packages\\IPython\\core\\interactiveshell.py\", line 2099, in showtraceback\n",
      "    stb = value._render_traceback_()\n",
      "AttributeError: 'TypeError' object has no attribute '_render_traceback_'\n",
      "\n",
      "During handling of the above exception, another exception occurred:\n",
      "\n",
      "Traceback (most recent call last):\n",
      "  File \"d:\\onedrive\\realtimeobjectdetection\\tensor\\lib\\site-packages\\IPython\\core\\interactiveshell.py\", line 3030, in _run_cell\n",
      "    return runner(coro)\n",
      "  File \"d:\\onedrive\\realtimeobjectdetection\\tensor\\lib\\site-packages\\IPython\\core\\async_helpers.py\", line 78, in _pseudo_sync_runner\n",
      "    coro.send(None)\n",
      "  File \"d:\\onedrive\\realtimeobjectdetection\\tensor\\lib\\site-packages\\IPython\\core\\interactiveshell.py\", line 3258, in run_cell_async\n",
      "    interactivity=interactivity, compiler=compiler, result=result)\n",
      "  File \"d:\\onedrive\\realtimeobjectdetection\\tensor\\lib\\site-packages\\IPython\\core\\interactiveshell.py\", line 3492, in run_ast_nodes\n",
      "    self.showtraceback()\n",
      "  File \"d:\\onedrive\\realtimeobjectdetection\\tensor\\lib\\site-packages\\IPython\\core\\interactiveshell.py\", line 2102, in showtraceback\n",
      "    value, tb, tb_offset=tb_offset)\n",
      "  File \"d:\\onedrive\\realtimeobjectdetection\\tensor\\lib\\site-packages\\IPython\\core\\ultratb.py\", line 1368, in structured_traceback\n",
      "    self, etype, value, tb, tb_offset, number_of_lines_of_context)\n",
      "  File \"d:\\onedrive\\realtimeobjectdetection\\tensor\\lib\\site-packages\\IPython\\core\\ultratb.py\", line 1268, in structured_traceback\n",
      "    self, etype, value, tb, tb_offset, number_of_lines_of_context\n",
      "  File \"d:\\onedrive\\realtimeobjectdetection\\tensor\\lib\\site-packages\\IPython\\core\\ultratb.py\", line 1143, in structured_traceback\n",
      "    chained_exceptions_tb_offset)\n",
      "  File \"d:\\onedrive\\realtimeobjectdetection\\tensor\\lib\\site-packages\\IPython\\core\\ultratb.py\", line 1082, in format_exception_as_a_whole\n",
      "    last_unique, recursion_repeat = find_recursion(orig_etype, evalue, records)\n",
      "  File \"d:\\onedrive\\realtimeobjectdetection\\tensor\\lib\\site-packages\\IPython\\core\\ultratb.py\", line 382, in find_recursion\n",
      "    return len(records), 0\n",
      "TypeError: object of type 'NoneType' has no len()\n",
      "\n",
      "During handling of the above exception, another exception occurred:\n",
      "\n",
      "Traceback (most recent call last):\n",
      "  File \"d:\\onedrive\\realtimeobjectdetection\\tensor\\lib\\site-packages\\IPython\\core\\interactiveshell.py\", line 2099, in showtraceback\n",
      "    stb = value._render_traceback_()\n",
      "AttributeError: 'TypeError' object has no attribute '_render_traceback_'\n",
      "\n",
      "During handling of the above exception, another exception occurred:\n",
      "\n",
      "Traceback (most recent call last):\n",
      "  File \"d:\\onedrive\\realtimeobjectdetection\\tensor\\lib\\site-packages\\IPython\\core\\ultratb.py\", line 1101, in get_records\n",
      "    return _fixed_getinnerframes(etb, number_of_lines_of_context, tb_offset)\n",
      "  File \"d:\\onedrive\\realtimeobjectdetection\\tensor\\lib\\site-packages\\IPython\\core\\ultratb.py\", line 248, in wrapped\n",
      "    return f(*args, **kwargs)\n",
      "  File \"d:\\onedrive\\realtimeobjectdetection\\tensor\\lib\\site-packages\\IPython\\core\\ultratb.py\", line 281, in _fixed_getinnerframes\n",
      "    records = fix_frame_records_filenames(inspect.getinnerframes(etb, context))\n",
      "  File \"C:\\python\\python37\\lib\\inspect.py\", line 1502, in getinnerframes\n",
      "    frameinfo = (tb.tb_frame,) + getframeinfo(tb, context)\n",
      "  File \"C:\\python\\python37\\lib\\inspect.py\", line 1460, in getframeinfo\n",
      "    filename = getsourcefile(frame) or getfile(frame)\n",
      "  File \"C:\\python\\python37\\lib\\inspect.py\", line 696, in getsourcefile\n",
      "    if getattr(getmodule(object, filename), '__loader__', None) is not None:\n",
      "  File \"C:\\python\\python37\\lib\\inspect.py\", line 733, in getmodule\n",
      "    if ismodule(module) and hasattr(module, '__file__'):\n",
      "  File \"d:\\onedrive\\realtimeobjectdetection\\tensor\\lib\\site-packages\\tensorflow\\__init__.py\", line 50, in __getattr__\n",
      "    module = self._load()\n",
      "  File \"d:\\onedrive\\realtimeobjectdetection\\tensor\\lib\\site-packages\\tensorflow\\__init__.py\", line 44, in _load\n",
      "    module = _importlib.import_module(self.__name__)\n",
      "  File \"C:\\python\\python37\\lib\\importlib\\__init__.py\", line 127, in import_module\n",
      "    return _bootstrap._gcd_import(name[level:], package, level)\n",
      "  File \"<frozen importlib._bootstrap>\", line 1006, in _gcd_import\n",
      "  File \"<frozen importlib._bootstrap>\", line 983, in _find_and_load\n",
      "  File \"<frozen importlib._bootstrap>\", line 953, in _find_and_load_unlocked\n",
      "  File \"<frozen importlib._bootstrap>\", line 219, in _call_with_frames_removed\n",
      "  File \"<frozen importlib._bootstrap>\", line 1006, in _gcd_import\n",
      "  File \"<frozen importlib._bootstrap>\", line 983, in _find_and_load\n",
      "  File \"<frozen importlib._bootstrap>\", line 967, in _find_and_load_unlocked\n",
      "  File \"<frozen importlib._bootstrap>\", line 677, in _load_unlocked\n",
      "  File \"<frozen importlib._bootstrap_external>\", line 728, in exec_module\n",
      "  File \"<frozen importlib._bootstrap>\", line 219, in _call_with_frames_removed\n",
      "  File \"d:\\onedrive\\realtimeobjectdetection\\tensor\\lib\\site-packages\\tensorflow_core\\__init__.py\", line 33, in <module>\n",
      "    from tensorflow._api.v1 import audio\n",
      "  File \"d:\\onedrive\\realtimeobjectdetection\\tensor\\lib\\site-packages\\tensorflow_core\\_api\\v1\\audio\\__init__.py\", line 10, in <module>\n",
      "    from tensorflow.python.ops.gen_audio_ops import decode_wav\n",
      "  File \"d:\\onedrive\\realtimeobjectdetection\\tensor\\lib\\site-packages\\tensorflow_core\\python\\ops\\gen_audio_ops.py\", line 10, in <module>\n",
      "    from tensorflow.python.eager import context as _context\n",
      "  File \"d:\\onedrive\\realtimeobjectdetection\\tensor\\lib\\site-packages\\tensorflow_core\\python\\eager\\context.py\", line 29, in <module>\n",
      "    from tensorflow.core.protobuf import config_pb2\n",
      "  File \"d:\\onedrive\\realtimeobjectdetection\\tensor\\lib\\site-packages\\tensorflow_core\\core\\protobuf\\config_pb2.py\", line 16, in <module>\n",
      "    from tensorflow.core.framework import cost_graph_pb2 as tensorflow_dot_core_dot_framework_dot_cost__graph__pb2\n",
      "  File \"d:\\onedrive\\realtimeobjectdetection\\tensor\\lib\\site-packages\\tensorflow_core\\core\\framework\\cost_graph_pb2.py\", line 16, in <module>\n",
      "    from tensorflow.core.framework import tensor_shape_pb2 as tensorflow_dot_core_dot_framework_dot_tensor__shape__pb2\n",
      "  File \"d:\\onedrive\\realtimeobjectdetection\\tensor\\lib\\site-packages\\tensorflow_core\\core\\framework\\tensor_shape_pb2.py\", line 42, in <module>\n",
      "    serialized_options=None, file=DESCRIPTOR),\n",
      "  File \"d:\\onedrive\\realtimeobjectdetection\\tensor\\lib\\site-packages\\google\\protobuf\\descriptor.py\", line 560, in __new__\n",
      "    return _message.default_pool.FindFieldByName(full_name)\n",
      "TypeError: Descriptors cannot not be created directly.\n",
      "If this call came from a _pb2.py file, your generated code is out of date and must be regenerated with protoc >= 3.19.0.\n",
      "If you cannot immediately regenerate your protos, some other possible workarounds are:\n",
      " 1. Downgrade the protobuf package to 3.20.x or lower.\n",
      " 2. Set PROTOCOL_BUFFERS_PYTHON_IMPLEMENTATION=python (but this will use pure-Python parsing and will be much slower).\n",
      "\n",
      "More information: https://developers.google.com/protocol-buffers/docs/news/2022-05-06#python-updates\n"
     ]
    }
   ],
   "source": [
    "config = config_util.get_configs_from_pipeline_file(CONFIG_PATH)"
   ]
  },
  {
   "cell_type": "code",
   "execution_count": 18,
   "metadata": {},
   "outputs": [
    {
     "name": "stdout",
     "output_type": "stream",
     "text": [
      "Available objects for config:\n",
      "     AliasManager\n",
      "     DisplayFormatter\n",
      "     HistoryManager\n",
      "     IPCompleter\n",
      "     IPKernelApp\n",
      "     LoggingMagics\n",
      "     MagicsManager\n",
      "     OSMagics\n",
      "     PrefilterManager\n",
      "     ScriptMagics\n",
      "     StoreMagics\n",
      "     ZMQInteractiveShell\n",
      "ERROR! Session/line number was not unique in database. History logging moved to new session 73\n"
     ]
    }
   ],
   "source": [
    "config"
   ]
  },
  {
   "cell_type": "code",
   "execution_count": null,
   "metadata": {},
   "outputs": [
    {
     "name": "stderr",
     "output_type": "stream",
     "text": [
      "ERROR:root:Internal Python error in the inspect module.\n",
      "Below is the traceback from this internal error.\n",
      "\n"
     ]
    },
    {
     "name": "stdout",
     "output_type": "stream",
     "text": [
      "Traceback (most recent call last):\n",
      "  File \"d:\\onedrive\\realtimeobjectdetection\\tensor\\lib\\site-packages\\IPython\\core\\interactiveshell.py\", line 3553, in run_code\n",
      "    exec(code_obj, self.user_global_ns, self.user_ns)\n",
      "  File \"C:\\Users\\HP\\AppData\\Local\\Temp\\ipykernel_9188\\3048533506.py\", line 1, in <module>\n",
      "    pipeline_config = pipeline_pb2.TrainEvalPipelineConfig()\n",
      "NameError: name 'pipeline_pb2' is not defined\n",
      "\n",
      "During handling of the above exception, another exception occurred:\n",
      "\n",
      "Traceback (most recent call last):\n",
      "  File \"d:\\onedrive\\realtimeobjectdetection\\tensor\\lib\\site-packages\\IPython\\core\\interactiveshell.py\", line 2099, in showtraceback\n",
      "    stb = value._render_traceback_()\n",
      "AttributeError: 'NameError' object has no attribute '_render_traceback_'\n",
      "\n",
      "During handling of the above exception, another exception occurred:\n",
      "\n",
      "Traceback (most recent call last):\n",
      "  File \"d:\\onedrive\\realtimeobjectdetection\\tensor\\lib\\site-packages\\IPython\\core\\ultratb.py\", line 1101, in get_records\n",
      "    return _fixed_getinnerframes(etb, number_of_lines_of_context, tb_offset)\n",
      "  File \"d:\\onedrive\\realtimeobjectdetection\\tensor\\lib\\site-packages\\IPython\\core\\ultratb.py\", line 248, in wrapped\n",
      "    return f(*args, **kwargs)\n",
      "  File \"d:\\onedrive\\realtimeobjectdetection\\tensor\\lib\\site-packages\\IPython\\core\\ultratb.py\", line 281, in _fixed_getinnerframes\n",
      "    records = fix_frame_records_filenames(inspect.getinnerframes(etb, context))\n",
      "  File \"C:\\python\\python37\\lib\\inspect.py\", line 1502, in getinnerframes\n",
      "    frameinfo = (tb.tb_frame,) + getframeinfo(tb, context)\n",
      "  File \"C:\\python\\python37\\lib\\inspect.py\", line 1460, in getframeinfo\n",
      "    filename = getsourcefile(frame) or getfile(frame)\n",
      "  File \"C:\\python\\python37\\lib\\inspect.py\", line 696, in getsourcefile\n",
      "    if getattr(getmodule(object, filename), '__loader__', None) is not None:\n",
      "  File \"C:\\python\\python37\\lib\\inspect.py\", line 733, in getmodule\n",
      "    if ismodule(module) and hasattr(module, '__file__'):\n",
      "  File \"d:\\onedrive\\realtimeobjectdetection\\tensor\\lib\\site-packages\\tensorflow\\__init__.py\", line 50, in __getattr__\n",
      "    module = self._load()\n",
      "  File \"d:\\onedrive\\realtimeobjectdetection\\tensor\\lib\\site-packages\\tensorflow\\__init__.py\", line 44, in _load\n",
      "    module = _importlib.import_module(self.__name__)\n",
      "  File \"C:\\python\\python37\\lib\\importlib\\__init__.py\", line 127, in import_module\n",
      "    return _bootstrap._gcd_import(name[level:], package, level)\n",
      "  File \"<frozen importlib._bootstrap>\", line 1006, in _gcd_import\n",
      "  File \"<frozen importlib._bootstrap>\", line 983, in _find_and_load\n",
      "  File \"<frozen importlib._bootstrap>\", line 953, in _find_and_load_unlocked\n",
      "  File \"<frozen importlib._bootstrap>\", line 219, in _call_with_frames_removed\n",
      "  File \"<frozen importlib._bootstrap>\", line 1006, in _gcd_import\n",
      "  File \"<frozen importlib._bootstrap>\", line 983, in _find_and_load\n",
      "  File \"<frozen importlib._bootstrap>\", line 967, in _find_and_load_unlocked\n",
      "  File \"<frozen importlib._bootstrap>\", line 677, in _load_unlocked\n",
      "  File \"<frozen importlib._bootstrap_external>\", line 728, in exec_module\n",
      "  File \"<frozen importlib._bootstrap>\", line 219, in _call_with_frames_removed\n",
      "  File \"d:\\onedrive\\realtimeobjectdetection\\tensor\\lib\\site-packages\\tensorflow_core\\__init__.py\", line 33, in <module>\n",
      "    from tensorflow._api.v1 import audio\n",
      "  File \"d:\\onedrive\\realtimeobjectdetection\\tensor\\lib\\site-packages\\tensorflow_core\\_api\\v1\\audio\\__init__.py\", line 10, in <module>\n",
      "    from tensorflow.python.ops.gen_audio_ops import decode_wav\n",
      "  File \"d:\\onedrive\\realtimeobjectdetection\\tensor\\lib\\site-packages\\tensorflow_core\\python\\ops\\gen_audio_ops.py\", line 10, in <module>\n",
      "    from tensorflow.python.eager import context as _context\n",
      "  File \"d:\\onedrive\\realtimeobjectdetection\\tensor\\lib\\site-packages\\tensorflow_core\\python\\eager\\context.py\", line 29, in <module>\n",
      "    from tensorflow.core.protobuf import config_pb2\n",
      "  File \"d:\\onedrive\\realtimeobjectdetection\\tensor\\lib\\site-packages\\tensorflow_core\\core\\protobuf\\config_pb2.py\", line 16, in <module>\n",
      "    from tensorflow.core.framework import cost_graph_pb2 as tensorflow_dot_core_dot_framework_dot_cost__graph__pb2\n",
      "  File \"d:\\onedrive\\realtimeobjectdetection\\tensor\\lib\\site-packages\\tensorflow_core\\core\\framework\\cost_graph_pb2.py\", line 16, in <module>\n",
      "    from tensorflow.core.framework import tensor_shape_pb2 as tensorflow_dot_core_dot_framework_dot_tensor__shape__pb2\n",
      "  File \"d:\\onedrive\\realtimeobjectdetection\\tensor\\lib\\site-packages\\tensorflow_core\\core\\framework\\tensor_shape_pb2.py\", line 42, in <module>\n",
      "    serialized_options=None, file=DESCRIPTOR),\n",
      "  File \"d:\\onedrive\\realtimeobjectdetection\\tensor\\lib\\site-packages\\google\\protobuf\\descriptor.py\", line 560, in __new__\n",
      "    return _message.default_pool.FindFieldByName(full_name)\n",
      "TypeError: Descriptors cannot not be created directly.\n",
      "If this call came from a _pb2.py file, your generated code is out of date and must be regenerated with protoc >= 3.19.0.\n",
      "If you cannot immediately regenerate your protos, some other possible workarounds are:\n",
      " 1. Downgrade the protobuf package to 3.20.x or lower.\n",
      " 2. Set PROTOCOL_BUFFERS_PYTHON_IMPLEMENTATION=python (but this will use pure-Python parsing and will be much slower).\n",
      "\n",
      "More information: https://developers.google.com/protocol-buffers/docs/news/2022-05-06#python-updates\n"
     ]
    },
    {
     "name": "stderr",
     "output_type": "stream",
     "text": [
      "ERROR:root:Internal Python error in the inspect module.\n",
      "Below is the traceback from this internal error.\n",
      "\n"
     ]
    },
    {
     "name": "stdout",
     "output_type": "stream",
     "text": [
      "Traceback (most recent call last):\n",
      "  File \"d:\\onedrive\\realtimeobjectdetection\\tensor\\lib\\site-packages\\IPython\\core\\interactiveshell.py\", line 3553, in run_code\n",
      "    exec(code_obj, self.user_global_ns, self.user_ns)\n",
      "  File \"C:\\Users\\HP\\AppData\\Local\\Temp\\ipykernel_9188\\3048533506.py\", line 1, in <module>\n",
      "    pipeline_config = pipeline_pb2.TrainEvalPipelineConfig()\n",
      "NameError: name 'pipeline_pb2' is not defined\n",
      "\n",
      "During handling of the above exception, another exception occurred:\n",
      "\n",
      "Traceback (most recent call last):\n",
      "  File \"d:\\onedrive\\realtimeobjectdetection\\tensor\\lib\\site-packages\\IPython\\core\\interactiveshell.py\", line 2099, in showtraceback\n",
      "    stb = value._render_traceback_()\n",
      "AttributeError: 'NameError' object has no attribute '_render_traceback_'\n",
      "\n",
      "During handling of the above exception, another exception occurred:\n",
      "\n",
      "Traceback (most recent call last):\n",
      "  File \"d:\\onedrive\\realtimeobjectdetection\\tensor\\lib\\site-packages\\IPython\\core\\interactiveshell.py\", line 3473, in run_ast_nodes\n",
      "    if (await self.run_code(code, result,  async_=asy)):\n",
      "  File \"d:\\onedrive\\realtimeobjectdetection\\tensor\\lib\\site-packages\\IPython\\core\\interactiveshell.py\", line 3575, in run_code\n",
      "    self.showtraceback(running_compiled_code=True)\n",
      "  File \"d:\\onedrive\\realtimeobjectdetection\\tensor\\lib\\site-packages\\IPython\\core\\interactiveshell.py\", line 2102, in showtraceback\n",
      "    value, tb, tb_offset=tb_offset)\n",
      "  File \"d:\\onedrive\\realtimeobjectdetection\\tensor\\lib\\site-packages\\IPython\\core\\ultratb.py\", line 1368, in structured_traceback\n",
      "    self, etype, value, tb, tb_offset, number_of_lines_of_context)\n",
      "  File \"d:\\onedrive\\realtimeobjectdetection\\tensor\\lib\\site-packages\\IPython\\core\\ultratb.py\", line 1268, in structured_traceback\n",
      "    self, etype, value, tb, tb_offset, number_of_lines_of_context\n",
      "  File \"d:\\onedrive\\realtimeobjectdetection\\tensor\\lib\\site-packages\\IPython\\core\\ultratb.py\", line 1125, in structured_traceback\n",
      "    tb_offset)\n",
      "  File \"d:\\onedrive\\realtimeobjectdetection\\tensor\\lib\\site-packages\\IPython\\core\\ultratb.py\", line 1082, in format_exception_as_a_whole\n",
      "    last_unique, recursion_repeat = find_recursion(orig_etype, evalue, records)\n",
      "  File \"d:\\onedrive\\realtimeobjectdetection\\tensor\\lib\\site-packages\\IPython\\core\\ultratb.py\", line 382, in find_recursion\n",
      "    return len(records), 0\n",
      "TypeError: object of type 'NoneType' has no len()\n",
      "\n",
      "During handling of the above exception, another exception occurred:\n",
      "\n",
      "Traceback (most recent call last):\n",
      "  File \"d:\\onedrive\\realtimeobjectdetection\\tensor\\lib\\site-packages\\IPython\\core\\interactiveshell.py\", line 2099, in showtraceback\n",
      "    stb = value._render_traceback_()\n",
      "AttributeError: 'TypeError' object has no attribute '_render_traceback_'\n",
      "\n",
      "During handling of the above exception, another exception occurred:\n",
      "\n",
      "Traceback (most recent call last):\n",
      "  File \"d:\\onedrive\\realtimeobjectdetection\\tensor\\lib\\site-packages\\IPython\\core\\ultratb.py\", line 1101, in get_records\n",
      "    return _fixed_getinnerframes(etb, number_of_lines_of_context, tb_offset)\n",
      "  File \"d:\\onedrive\\realtimeobjectdetection\\tensor\\lib\\site-packages\\IPython\\core\\ultratb.py\", line 248, in wrapped\n",
      "    return f(*args, **kwargs)\n",
      "  File \"d:\\onedrive\\realtimeobjectdetection\\tensor\\lib\\site-packages\\IPython\\core\\ultratb.py\", line 281, in _fixed_getinnerframes\n",
      "    records = fix_frame_records_filenames(inspect.getinnerframes(etb, context))\n",
      "  File \"C:\\python\\python37\\lib\\inspect.py\", line 1502, in getinnerframes\n",
      "    frameinfo = (tb.tb_frame,) + getframeinfo(tb, context)\n",
      "  File \"C:\\python\\python37\\lib\\inspect.py\", line 1460, in getframeinfo\n",
      "    filename = getsourcefile(frame) or getfile(frame)\n",
      "  File \"C:\\python\\python37\\lib\\inspect.py\", line 696, in getsourcefile\n",
      "    if getattr(getmodule(object, filename), '__loader__', None) is not None:\n",
      "  File \"C:\\python\\python37\\lib\\inspect.py\", line 733, in getmodule\n",
      "    if ismodule(module) and hasattr(module, '__file__'):\n",
      "  File \"d:\\onedrive\\realtimeobjectdetection\\tensor\\lib\\site-packages\\tensorflow\\__init__.py\", line 50, in __getattr__\n",
      "    module = self._load()\n",
      "  File \"d:\\onedrive\\realtimeobjectdetection\\tensor\\lib\\site-packages\\tensorflow\\__init__.py\", line 44, in _load\n",
      "    module = _importlib.import_module(self.__name__)\n",
      "  File \"C:\\python\\python37\\lib\\importlib\\__init__.py\", line 127, in import_module\n",
      "    return _bootstrap._gcd_import(name[level:], package, level)\n",
      "  File \"<frozen importlib._bootstrap>\", line 1006, in _gcd_import\n",
      "  File \"<frozen importlib._bootstrap>\", line 983, in _find_and_load\n",
      "  File \"<frozen importlib._bootstrap>\", line 953, in _find_and_load_unlocked\n",
      "  File \"<frozen importlib._bootstrap>\", line 219, in _call_with_frames_removed\n",
      "  File \"<frozen importlib._bootstrap>\", line 1006, in _gcd_import\n",
      "  File \"<frozen importlib._bootstrap>\", line 983, in _find_and_load\n",
      "  File \"<frozen importlib._bootstrap>\", line 967, in _find_and_load_unlocked\n",
      "  File \"<frozen importlib._bootstrap>\", line 677, in _load_unlocked\n",
      "  File \"<frozen importlib._bootstrap_external>\", line 728, in exec_module\n",
      "  File \"<frozen importlib._bootstrap>\", line 219, in _call_with_frames_removed\n",
      "  File \"d:\\onedrive\\realtimeobjectdetection\\tensor\\lib\\site-packages\\tensorflow_core\\__init__.py\", line 33, in <module>\n",
      "    from tensorflow._api.v1 import audio\n",
      "  File \"d:\\onedrive\\realtimeobjectdetection\\tensor\\lib\\site-packages\\tensorflow_core\\_api\\v1\\audio\\__init__.py\", line 10, in <module>\n",
      "    from tensorflow.python.ops.gen_audio_ops import decode_wav\n",
      "  File \"d:\\onedrive\\realtimeobjectdetection\\tensor\\lib\\site-packages\\tensorflow_core\\python\\ops\\gen_audio_ops.py\", line 10, in <module>\n",
      "    from tensorflow.python.eager import context as _context\n",
      "  File \"d:\\onedrive\\realtimeobjectdetection\\tensor\\lib\\site-packages\\tensorflow_core\\python\\eager\\context.py\", line 29, in <module>\n",
      "    from tensorflow.core.protobuf import config_pb2\n",
      "  File \"d:\\onedrive\\realtimeobjectdetection\\tensor\\lib\\site-packages\\tensorflow_core\\core\\protobuf\\config_pb2.py\", line 16, in <module>\n",
      "    from tensorflow.core.framework import cost_graph_pb2 as tensorflow_dot_core_dot_framework_dot_cost__graph__pb2\n",
      "  File \"d:\\onedrive\\realtimeobjectdetection\\tensor\\lib\\site-packages\\tensorflow_core\\core\\framework\\cost_graph_pb2.py\", line 16, in <module>\n",
      "    from tensorflow.core.framework import tensor_shape_pb2 as tensorflow_dot_core_dot_framework_dot_tensor__shape__pb2\n",
      "  File \"d:\\onedrive\\realtimeobjectdetection\\tensor\\lib\\site-packages\\tensorflow_core\\core\\framework\\tensor_shape_pb2.py\", line 42, in <module>\n",
      "    serialized_options=None, file=DESCRIPTOR),\n",
      "  File \"d:\\onedrive\\realtimeobjectdetection\\tensor\\lib\\site-packages\\google\\protobuf\\descriptor.py\", line 560, in __new__\n",
      "    return _message.default_pool.FindFieldByName(full_name)\n",
      "TypeError: Descriptors cannot not be created directly.\n",
      "If this call came from a _pb2.py file, your generated code is out of date and must be regenerated with protoc >= 3.19.0.\n",
      "If you cannot immediately regenerate your protos, some other possible workarounds are:\n",
      " 1. Downgrade the protobuf package to 3.20.x or lower.\n",
      " 2. Set PROTOCOL_BUFFERS_PYTHON_IMPLEMENTATION=python (but this will use pure-Python parsing and will be much slower).\n",
      "\n",
      "More information: https://developers.google.com/protocol-buffers/docs/news/2022-05-06#python-updates\n"
     ]
    },
    {
     "name": "stderr",
     "output_type": "stream",
     "text": [
      "ERROR:root:Internal Python error in the inspect module.\n",
      "Below is the traceback from this internal error.\n",
      "\n"
     ]
    },
    {
     "name": "stdout",
     "output_type": "stream",
     "text": [
      "Traceback (most recent call last):\n",
      "  File \"d:\\onedrive\\realtimeobjectdetection\\tensor\\lib\\site-packages\\IPython\\core\\interactiveshell.py\", line 3553, in run_code\n",
      "    exec(code_obj, self.user_global_ns, self.user_ns)\n",
      "  File \"C:\\Users\\HP\\AppData\\Local\\Temp\\ipykernel_9188\\3048533506.py\", line 1, in <module>\n",
      "    pipeline_config = pipeline_pb2.TrainEvalPipelineConfig()\n",
      "NameError: name 'pipeline_pb2' is not defined\n",
      "\n",
      "During handling of the above exception, another exception occurred:\n",
      "\n",
      "Traceback (most recent call last):\n",
      "  File \"d:\\onedrive\\realtimeobjectdetection\\tensor\\lib\\site-packages\\IPython\\core\\interactiveshell.py\", line 2099, in showtraceback\n",
      "    stb = value._render_traceback_()\n",
      "AttributeError: 'NameError' object has no attribute '_render_traceback_'\n",
      "\n",
      "During handling of the above exception, another exception occurred:\n",
      "\n",
      "Traceback (most recent call last):\n",
      "  File \"d:\\onedrive\\realtimeobjectdetection\\tensor\\lib\\site-packages\\IPython\\core\\interactiveshell.py\", line 3473, in run_ast_nodes\n",
      "    if (await self.run_code(code, result,  async_=asy)):\n",
      "  File \"d:\\onedrive\\realtimeobjectdetection\\tensor\\lib\\site-packages\\IPython\\core\\interactiveshell.py\", line 3575, in run_code\n",
      "    self.showtraceback(running_compiled_code=True)\n",
      "  File \"d:\\onedrive\\realtimeobjectdetection\\tensor\\lib\\site-packages\\IPython\\core\\interactiveshell.py\", line 2102, in showtraceback\n",
      "    value, tb, tb_offset=tb_offset)\n",
      "  File \"d:\\onedrive\\realtimeobjectdetection\\tensor\\lib\\site-packages\\IPython\\core\\ultratb.py\", line 1368, in structured_traceback\n",
      "    self, etype, value, tb, tb_offset, number_of_lines_of_context)\n",
      "  File \"d:\\onedrive\\realtimeobjectdetection\\tensor\\lib\\site-packages\\IPython\\core\\ultratb.py\", line 1268, in structured_traceback\n",
      "    self, etype, value, tb, tb_offset, number_of_lines_of_context\n",
      "  File \"d:\\onedrive\\realtimeobjectdetection\\tensor\\lib\\site-packages\\IPython\\core\\ultratb.py\", line 1125, in structured_traceback\n",
      "    tb_offset)\n",
      "  File \"d:\\onedrive\\realtimeobjectdetection\\tensor\\lib\\site-packages\\IPython\\core\\ultratb.py\", line 1082, in format_exception_as_a_whole\n",
      "    last_unique, recursion_repeat = find_recursion(orig_etype, evalue, records)\n",
      "  File \"d:\\onedrive\\realtimeobjectdetection\\tensor\\lib\\site-packages\\IPython\\core\\ultratb.py\", line 382, in find_recursion\n",
      "    return len(records), 0\n",
      "TypeError: object of type 'NoneType' has no len()\n",
      "\n",
      "During handling of the above exception, another exception occurred:\n",
      "\n",
      "Traceback (most recent call last):\n",
      "  File \"d:\\onedrive\\realtimeobjectdetection\\tensor\\lib\\site-packages\\IPython\\core\\interactiveshell.py\", line 2099, in showtraceback\n",
      "    stb = value._render_traceback_()\n",
      "AttributeError: 'TypeError' object has no attribute '_render_traceback_'\n",
      "\n",
      "During handling of the above exception, another exception occurred:\n",
      "\n",
      "Traceback (most recent call last):\n",
      "  File \"d:\\onedrive\\realtimeobjectdetection\\tensor\\lib\\site-packages\\IPython\\core\\interactiveshell.py\", line 3030, in _run_cell\n",
      "    return runner(coro)\n",
      "  File \"d:\\onedrive\\realtimeobjectdetection\\tensor\\lib\\site-packages\\IPython\\core\\async_helpers.py\", line 78, in _pseudo_sync_runner\n",
      "    coro.send(None)\n",
      "  File \"d:\\onedrive\\realtimeobjectdetection\\tensor\\lib\\site-packages\\IPython\\core\\interactiveshell.py\", line 3258, in run_cell_async\n",
      "    interactivity=interactivity, compiler=compiler, result=result)\n",
      "  File \"d:\\onedrive\\realtimeobjectdetection\\tensor\\lib\\site-packages\\IPython\\core\\interactiveshell.py\", line 3492, in run_ast_nodes\n",
      "    self.showtraceback()\n",
      "  File \"d:\\onedrive\\realtimeobjectdetection\\tensor\\lib\\site-packages\\IPython\\core\\interactiveshell.py\", line 2102, in showtraceback\n",
      "    value, tb, tb_offset=tb_offset)\n",
      "  File \"d:\\onedrive\\realtimeobjectdetection\\tensor\\lib\\site-packages\\IPython\\core\\ultratb.py\", line 1368, in structured_traceback\n",
      "    self, etype, value, tb, tb_offset, number_of_lines_of_context)\n",
      "  File \"d:\\onedrive\\realtimeobjectdetection\\tensor\\lib\\site-packages\\IPython\\core\\ultratb.py\", line 1268, in structured_traceback\n",
      "    self, etype, value, tb, tb_offset, number_of_lines_of_context\n",
      "  File \"d:\\onedrive\\realtimeobjectdetection\\tensor\\lib\\site-packages\\IPython\\core\\ultratb.py\", line 1143, in structured_traceback\n",
      "    chained_exceptions_tb_offset)\n",
      "  File \"d:\\onedrive\\realtimeobjectdetection\\tensor\\lib\\site-packages\\IPython\\core\\ultratb.py\", line 1082, in format_exception_as_a_whole\n",
      "    last_unique, recursion_repeat = find_recursion(orig_etype, evalue, records)\n",
      "  File \"d:\\onedrive\\realtimeobjectdetection\\tensor\\lib\\site-packages\\IPython\\core\\ultratb.py\", line 382, in find_recursion\n",
      "    return len(records), 0\n",
      "TypeError: object of type 'NoneType' has no len()\n",
      "\n",
      "During handling of the above exception, another exception occurred:\n",
      "\n",
      "Traceback (most recent call last):\n",
      "  File \"d:\\onedrive\\realtimeobjectdetection\\tensor\\lib\\site-packages\\IPython\\core\\interactiveshell.py\", line 2099, in showtraceback\n",
      "    stb = value._render_traceback_()\n",
      "AttributeError: 'TypeError' object has no attribute '_render_traceback_'\n",
      "\n",
      "During handling of the above exception, another exception occurred:\n",
      "\n",
      "Traceback (most recent call last):\n",
      "  File \"d:\\onedrive\\realtimeobjectdetection\\tensor\\lib\\site-packages\\IPython\\core\\ultratb.py\", line 1101, in get_records\n",
      "    return _fixed_getinnerframes(etb, number_of_lines_of_context, tb_offset)\n",
      "  File \"d:\\onedrive\\realtimeobjectdetection\\tensor\\lib\\site-packages\\IPython\\core\\ultratb.py\", line 248, in wrapped\n",
      "    return f(*args, **kwargs)\n",
      "  File \"d:\\onedrive\\realtimeobjectdetection\\tensor\\lib\\site-packages\\IPython\\core\\ultratb.py\", line 281, in _fixed_getinnerframes\n",
      "    records = fix_frame_records_filenames(inspect.getinnerframes(etb, context))\n",
      "  File \"C:\\python\\python37\\lib\\inspect.py\", line 1502, in getinnerframes\n",
      "    frameinfo = (tb.tb_frame,) + getframeinfo(tb, context)\n",
      "  File \"C:\\python\\python37\\lib\\inspect.py\", line 1460, in getframeinfo\n",
      "    filename = getsourcefile(frame) or getfile(frame)\n",
      "  File \"C:\\python\\python37\\lib\\inspect.py\", line 696, in getsourcefile\n",
      "    if getattr(getmodule(object, filename), '__loader__', None) is not None:\n",
      "  File \"C:\\python\\python37\\lib\\inspect.py\", line 733, in getmodule\n",
      "    if ismodule(module) and hasattr(module, '__file__'):\n",
      "  File \"d:\\onedrive\\realtimeobjectdetection\\tensor\\lib\\site-packages\\tensorflow\\__init__.py\", line 50, in __getattr__\n",
      "    module = self._load()\n",
      "  File \"d:\\onedrive\\realtimeobjectdetection\\tensor\\lib\\site-packages\\tensorflow\\__init__.py\", line 44, in _load\n",
      "    module = _importlib.import_module(self.__name__)\n",
      "  File \"C:\\python\\python37\\lib\\importlib\\__init__.py\", line 127, in import_module\n",
      "    return _bootstrap._gcd_import(name[level:], package, level)\n",
      "  File \"<frozen importlib._bootstrap>\", line 1006, in _gcd_import\n",
      "  File \"<frozen importlib._bootstrap>\", line 983, in _find_and_load\n",
      "  File \"<frozen importlib._bootstrap>\", line 953, in _find_and_load_unlocked\n",
      "  File \"<frozen importlib._bootstrap>\", line 219, in _call_with_frames_removed\n",
      "  File \"<frozen importlib._bootstrap>\", line 1006, in _gcd_import\n",
      "  File \"<frozen importlib._bootstrap>\", line 983, in _find_and_load\n",
      "  File \"<frozen importlib._bootstrap>\", line 967, in _find_and_load_unlocked\n",
      "  File \"<frozen importlib._bootstrap>\", line 677, in _load_unlocked\n",
      "  File \"<frozen importlib._bootstrap_external>\", line 728, in exec_module\n",
      "  File \"<frozen importlib._bootstrap>\", line 219, in _call_with_frames_removed\n",
      "  File \"d:\\onedrive\\realtimeobjectdetection\\tensor\\lib\\site-packages\\tensorflow_core\\__init__.py\", line 33, in <module>\n",
      "    from tensorflow._api.v1 import audio\n",
      "  File \"d:\\onedrive\\realtimeobjectdetection\\tensor\\lib\\site-packages\\tensorflow_core\\_api\\v1\\audio\\__init__.py\", line 10, in <module>\n",
      "    from tensorflow.python.ops.gen_audio_ops import decode_wav\n",
      "  File \"d:\\onedrive\\realtimeobjectdetection\\tensor\\lib\\site-packages\\tensorflow_core\\python\\ops\\gen_audio_ops.py\", line 10, in <module>\n",
      "    from tensorflow.python.eager import context as _context\n",
      "  File \"d:\\onedrive\\realtimeobjectdetection\\tensor\\lib\\site-packages\\tensorflow_core\\python\\eager\\context.py\", line 29, in <module>\n",
      "    from tensorflow.core.protobuf import config_pb2\n",
      "  File \"d:\\onedrive\\realtimeobjectdetection\\tensor\\lib\\site-packages\\tensorflow_core\\core\\protobuf\\config_pb2.py\", line 16, in <module>\n",
      "    from tensorflow.core.framework import cost_graph_pb2 as tensorflow_dot_core_dot_framework_dot_cost__graph__pb2\n",
      "  File \"d:\\onedrive\\realtimeobjectdetection\\tensor\\lib\\site-packages\\tensorflow_core\\core\\framework\\cost_graph_pb2.py\", line 16, in <module>\n",
      "    from tensorflow.core.framework import tensor_shape_pb2 as tensorflow_dot_core_dot_framework_dot_tensor__shape__pb2\n",
      "  File \"d:\\onedrive\\realtimeobjectdetection\\tensor\\lib\\site-packages\\tensorflow_core\\core\\framework\\tensor_shape_pb2.py\", line 42, in <module>\n",
      "    serialized_options=None, file=DESCRIPTOR),\n",
      "  File \"d:\\onedrive\\realtimeobjectdetection\\tensor\\lib\\site-packages\\google\\protobuf\\descriptor.py\", line 560, in __new__\n",
      "    return _message.default_pool.FindFieldByName(full_name)\n",
      "TypeError: Descriptors cannot not be created directly.\n",
      "If this call came from a _pb2.py file, your generated code is out of date and must be regenerated with protoc >= 3.19.0.\n",
      "If you cannot immediately regenerate your protos, some other possible workarounds are:\n",
      " 1. Downgrade the protobuf package to 3.20.x or lower.\n",
      " 2. Set PROTOCOL_BUFFERS_PYTHON_IMPLEMENTATION=python (but this will use pure-Python parsing and will be much slower).\n",
      "\n",
      "More information: https://developers.google.com/protocol-buffers/docs/news/2022-05-06#python-updates\n"
     ]
    }
   ],
   "source": [
    "pipeline_config = pipeline_pb2.TrainEvalPipelineConfig()\n",
    "with tf.gfile.GFile(CONFIG_PATH, \"r\") as f:                                                                                                                                                                                                                     \n",
    "    proto_str = f.read()                                                                                                                                                                                                                                          \n",
    "    text_format.Merge(proto_str, pipeline_config)  "
   ]
  },
  {
   "cell_type": "code",
   "execution_count": null,
   "metadata": {},
   "outputs": [
    {
     "name": "stderr",
     "output_type": "stream",
     "text": [
      "ERROR:root:Internal Python error in the inspect module.\n",
      "Below is the traceback from this internal error.\n",
      "\n",
      "ERROR:root:Internal Python error in the inspect module.\n",
      "Below is the traceback from this internal error.\n",
      "\n",
      "ERROR:root:Internal Python error in the inspect module.\n",
      "Below is the traceback from this internal error.\n",
      "\n"
     ]
    },
    {
     "name": "stdout",
     "output_type": "stream",
     "text": [
      "Traceback (most recent call last):\n",
      "  File \"d:\\onedrive\\realtimeobjectdetection\\tensor\\lib\\site-packages\\IPython\\core\\interactiveshell.py\", line 3553, in run_code\n",
      "    exec(code_obj, self.user_global_ns, self.user_ns)\n",
      "  File \"C:\\Users\\HP\\AppData\\Local\\Temp\\ipykernel_9188\\3885242755.py\", line 1, in <module>\n",
      "    pipeline_config.model.ssd.num_classes = 2\n",
      "NameError: name 'pipeline_config' is not defined\n",
      "\n",
      "During handling of the above exception, another exception occurred:\n",
      "\n",
      "Traceback (most recent call last):\n",
      "  File \"d:\\onedrive\\realtimeobjectdetection\\tensor\\lib\\site-packages\\IPython\\core\\interactiveshell.py\", line 2099, in showtraceback\n",
      "    stb = value._render_traceback_()\n",
      "AttributeError: 'NameError' object has no attribute '_render_traceback_'\n",
      "\n",
      "During handling of the above exception, another exception occurred:\n",
      "\n",
      "Traceback (most recent call last):\n",
      "  File \"d:\\onedrive\\realtimeobjectdetection\\tensor\\lib\\site-packages\\IPython\\core\\ultratb.py\", line 1101, in get_records\n",
      "    return _fixed_getinnerframes(etb, number_of_lines_of_context, tb_offset)\n",
      "  File \"d:\\onedrive\\realtimeobjectdetection\\tensor\\lib\\site-packages\\IPython\\core\\ultratb.py\", line 248, in wrapped\n",
      "    return f(*args, **kwargs)\n",
      "  File \"d:\\onedrive\\realtimeobjectdetection\\tensor\\lib\\site-packages\\IPython\\core\\ultratb.py\", line 281, in _fixed_getinnerframes\n",
      "    records = fix_frame_records_filenames(inspect.getinnerframes(etb, context))\n",
      "  File \"C:\\python\\python37\\lib\\inspect.py\", line 1502, in getinnerframes\n",
      "    frameinfo = (tb.tb_frame,) + getframeinfo(tb, context)\n",
      "  File \"C:\\python\\python37\\lib\\inspect.py\", line 1460, in getframeinfo\n",
      "    filename = getsourcefile(frame) or getfile(frame)\n",
      "  File \"C:\\python\\python37\\lib\\inspect.py\", line 696, in getsourcefile\n",
      "    if getattr(getmodule(object, filename), '__loader__', None) is not None:\n",
      "  File \"C:\\python\\python37\\lib\\inspect.py\", line 733, in getmodule\n",
      "    if ismodule(module) and hasattr(module, '__file__'):\n",
      "  File \"d:\\onedrive\\realtimeobjectdetection\\tensor\\lib\\site-packages\\tensorflow\\__init__.py\", line 50, in __getattr__\n",
      "    module = self._load()\n",
      "  File \"d:\\onedrive\\realtimeobjectdetection\\tensor\\lib\\site-packages\\tensorflow\\__init__.py\", line 44, in _load\n",
      "    module = _importlib.import_module(self.__name__)\n",
      "  File \"C:\\python\\python37\\lib\\importlib\\__init__.py\", line 127, in import_module\n",
      "    return _bootstrap._gcd_import(name[level:], package, level)\n",
      "  File \"<frozen importlib._bootstrap>\", line 1006, in _gcd_import\n",
      "  File \"<frozen importlib._bootstrap>\", line 983, in _find_and_load\n",
      "  File \"<frozen importlib._bootstrap>\", line 953, in _find_and_load_unlocked\n",
      "  File \"<frozen importlib._bootstrap>\", line 219, in _call_with_frames_removed\n",
      "  File \"<frozen importlib._bootstrap>\", line 1006, in _gcd_import\n",
      "  File \"<frozen importlib._bootstrap>\", line 983, in _find_and_load\n",
      "  File \"<frozen importlib._bootstrap>\", line 967, in _find_and_load_unlocked\n",
      "  File \"<frozen importlib._bootstrap>\", line 677, in _load_unlocked\n",
      "  File \"<frozen importlib._bootstrap_external>\", line 728, in exec_module\n",
      "  File \"<frozen importlib._bootstrap>\", line 219, in _call_with_frames_removed\n",
      "  File \"d:\\onedrive\\realtimeobjectdetection\\tensor\\lib\\site-packages\\tensorflow_core\\__init__.py\", line 33, in <module>\n",
      "    from tensorflow._api.v1 import audio\n",
      "  File \"d:\\onedrive\\realtimeobjectdetection\\tensor\\lib\\site-packages\\tensorflow_core\\_api\\v1\\audio\\__init__.py\", line 10, in <module>\n",
      "    from tensorflow.python.ops.gen_audio_ops import decode_wav\n",
      "  File \"d:\\onedrive\\realtimeobjectdetection\\tensor\\lib\\site-packages\\tensorflow_core\\python\\ops\\gen_audio_ops.py\", line 10, in <module>\n",
      "    from tensorflow.python.eager import context as _context\n",
      "  File \"d:\\onedrive\\realtimeobjectdetection\\tensor\\lib\\site-packages\\tensorflow_core\\python\\eager\\context.py\", line 29, in <module>\n",
      "    from tensorflow.core.protobuf import config_pb2\n",
      "  File \"d:\\onedrive\\realtimeobjectdetection\\tensor\\lib\\site-packages\\tensorflow_core\\core\\protobuf\\config_pb2.py\", line 16, in <module>\n",
      "    from tensorflow.core.framework import cost_graph_pb2 as tensorflow_dot_core_dot_framework_dot_cost__graph__pb2\n",
      "  File \"d:\\onedrive\\realtimeobjectdetection\\tensor\\lib\\site-packages\\tensorflow_core\\core\\framework\\cost_graph_pb2.py\", line 16, in <module>\n",
      "    from tensorflow.core.framework import tensor_shape_pb2 as tensorflow_dot_core_dot_framework_dot_tensor__shape__pb2\n",
      "  File \"d:\\onedrive\\realtimeobjectdetection\\tensor\\lib\\site-packages\\tensorflow_core\\core\\framework\\tensor_shape_pb2.py\", line 42, in <module>\n",
      "    serialized_options=None, file=DESCRIPTOR),\n",
      "  File \"d:\\onedrive\\realtimeobjectdetection\\tensor\\lib\\site-packages\\google\\protobuf\\descriptor.py\", line 560, in __new__\n",
      "    return _message.default_pool.FindFieldByName(full_name)\n",
      "TypeError: Descriptors cannot not be created directly.\n",
      "If this call came from a _pb2.py file, your generated code is out of date and must be regenerated with protoc >= 3.19.0.\n",
      "If you cannot immediately regenerate your protos, some other possible workarounds are:\n",
      " 1. Downgrade the protobuf package to 3.20.x or lower.\n",
      " 2. Set PROTOCOL_BUFFERS_PYTHON_IMPLEMENTATION=python (but this will use pure-Python parsing and will be much slower).\n",
      "\n",
      "More information: https://developers.google.com/protocol-buffers/docs/news/2022-05-06#python-updates\n",
      "Traceback (most recent call last):\n",
      "  File \"d:\\onedrive\\realtimeobjectdetection\\tensor\\lib\\site-packages\\IPython\\core\\interactiveshell.py\", line 3553, in run_code\n",
      "    exec(code_obj, self.user_global_ns, self.user_ns)\n",
      "  File \"C:\\Users\\HP\\AppData\\Local\\Temp\\ipykernel_9188\\3885242755.py\", line 1, in <module>\n",
      "    pipeline_config.model.ssd.num_classes = 2\n",
      "NameError: name 'pipeline_config' is not defined\n",
      "\n",
      "During handling of the above exception, another exception occurred:\n",
      "\n",
      "Traceback (most recent call last):\n",
      "  File \"d:\\onedrive\\realtimeobjectdetection\\tensor\\lib\\site-packages\\IPython\\core\\interactiveshell.py\", line 2099, in showtraceback\n",
      "    stb = value._render_traceback_()\n",
      "AttributeError: 'NameError' object has no attribute '_render_traceback_'\n",
      "\n",
      "During handling of the above exception, another exception occurred:\n",
      "\n",
      "Traceback (most recent call last):\n",
      "  File \"d:\\onedrive\\realtimeobjectdetection\\tensor\\lib\\site-packages\\IPython\\core\\interactiveshell.py\", line 3473, in run_ast_nodes\n",
      "    if (await self.run_code(code, result,  async_=asy)):\n",
      "  File \"d:\\onedrive\\realtimeobjectdetection\\tensor\\lib\\site-packages\\IPython\\core\\interactiveshell.py\", line 3575, in run_code\n",
      "    self.showtraceback(running_compiled_code=True)\n",
      "  File \"d:\\onedrive\\realtimeobjectdetection\\tensor\\lib\\site-packages\\IPython\\core\\interactiveshell.py\", line 2102, in showtraceback\n",
      "    value, tb, tb_offset=tb_offset)\n",
      "  File \"d:\\onedrive\\realtimeobjectdetection\\tensor\\lib\\site-packages\\IPython\\core\\ultratb.py\", line 1368, in structured_traceback\n",
      "    self, etype, value, tb, tb_offset, number_of_lines_of_context)\n",
      "  File \"d:\\onedrive\\realtimeobjectdetection\\tensor\\lib\\site-packages\\IPython\\core\\ultratb.py\", line 1268, in structured_traceback\n",
      "    self, etype, value, tb, tb_offset, number_of_lines_of_context\n",
      "  File \"d:\\onedrive\\realtimeobjectdetection\\tensor\\lib\\site-packages\\IPython\\core\\ultratb.py\", line 1125, in structured_traceback\n",
      "    tb_offset)\n",
      "  File \"d:\\onedrive\\realtimeobjectdetection\\tensor\\lib\\site-packages\\IPython\\core\\ultratb.py\", line 1082, in format_exception_as_a_whole\n",
      "    last_unique, recursion_repeat = find_recursion(orig_etype, evalue, records)\n",
      "  File \"d:\\onedrive\\realtimeobjectdetection\\tensor\\lib\\site-packages\\IPython\\core\\ultratb.py\", line 382, in find_recursion\n",
      "    return len(records), 0\n",
      "TypeError: object of type 'NoneType' has no len()\n",
      "\n",
      "During handling of the above exception, another exception occurred:\n",
      "\n",
      "Traceback (most recent call last):\n",
      "  File \"d:\\onedrive\\realtimeobjectdetection\\tensor\\lib\\site-packages\\IPython\\core\\interactiveshell.py\", line 2099, in showtraceback\n",
      "    stb = value._render_traceback_()\n",
      "AttributeError: 'TypeError' object has no attribute '_render_traceback_'\n",
      "\n",
      "During handling of the above exception, another exception occurred:\n",
      "\n",
      "Traceback (most recent call last):\n",
      "  File \"d:\\onedrive\\realtimeobjectdetection\\tensor\\lib\\site-packages\\IPython\\core\\ultratb.py\", line 1101, in get_records\n",
      "    return _fixed_getinnerframes(etb, number_of_lines_of_context, tb_offset)\n",
      "  File \"d:\\onedrive\\realtimeobjectdetection\\tensor\\lib\\site-packages\\IPython\\core\\ultratb.py\", line 248, in wrapped\n",
      "    return f(*args, **kwargs)\n",
      "  File \"d:\\onedrive\\realtimeobjectdetection\\tensor\\lib\\site-packages\\IPython\\core\\ultratb.py\", line 281, in _fixed_getinnerframes\n",
      "    records = fix_frame_records_filenames(inspect.getinnerframes(etb, context))\n",
      "  File \"C:\\python\\python37\\lib\\inspect.py\", line 1502, in getinnerframes\n",
      "    frameinfo = (tb.tb_frame,) + getframeinfo(tb, context)\n",
      "  File \"C:\\python\\python37\\lib\\inspect.py\", line 1460, in getframeinfo\n",
      "    filename = getsourcefile(frame) or getfile(frame)\n",
      "  File \"C:\\python\\python37\\lib\\inspect.py\", line 696, in getsourcefile\n",
      "    if getattr(getmodule(object, filename), '__loader__', None) is not None:\n",
      "  File \"C:\\python\\python37\\lib\\inspect.py\", line 733, in getmodule\n",
      "    if ismodule(module) and hasattr(module, '__file__'):\n",
      "  File \"d:\\onedrive\\realtimeobjectdetection\\tensor\\lib\\site-packages\\tensorflow\\__init__.py\", line 50, in __getattr__\n",
      "    module = self._load()\n",
      "  File \"d:\\onedrive\\realtimeobjectdetection\\tensor\\lib\\site-packages\\tensorflow\\__init__.py\", line 44, in _load\n",
      "    module = _importlib.import_module(self.__name__)\n",
      "  File \"C:\\python\\python37\\lib\\importlib\\__init__.py\", line 127, in import_module\n",
      "    return _bootstrap._gcd_import(name[level:], package, level)\n",
      "  File \"<frozen importlib._bootstrap>\", line 1006, in _gcd_import\n",
      "  File \"<frozen importlib._bootstrap>\", line 983, in _find_and_load\n",
      "  File \"<frozen importlib._bootstrap>\", line 953, in _find_and_load_unlocked\n",
      "  File \"<frozen importlib._bootstrap>\", line 219, in _call_with_frames_removed\n",
      "  File \"<frozen importlib._bootstrap>\", line 1006, in _gcd_import\n",
      "  File \"<frozen importlib._bootstrap>\", line 983, in _find_and_load\n",
      "  File \"<frozen importlib._bootstrap>\", line 967, in _find_and_load_unlocked\n",
      "  File \"<frozen importlib._bootstrap>\", line 677, in _load_unlocked\n",
      "  File \"<frozen importlib._bootstrap_external>\", line 728, in exec_module\n",
      "  File \"<frozen importlib._bootstrap>\", line 219, in _call_with_frames_removed\n",
      "  File \"d:\\onedrive\\realtimeobjectdetection\\tensor\\lib\\site-packages\\tensorflow_core\\__init__.py\", line 33, in <module>\n",
      "    from tensorflow._api.v1 import audio\n",
      "  File \"d:\\onedrive\\realtimeobjectdetection\\tensor\\lib\\site-packages\\tensorflow_core\\_api\\v1\\audio\\__init__.py\", line 10, in <module>\n",
      "    from tensorflow.python.ops.gen_audio_ops import decode_wav\n",
      "  File \"d:\\onedrive\\realtimeobjectdetection\\tensor\\lib\\site-packages\\tensorflow_core\\python\\ops\\gen_audio_ops.py\", line 10, in <module>\n",
      "    from tensorflow.python.eager import context as _context\n",
      "  File \"d:\\onedrive\\realtimeobjectdetection\\tensor\\lib\\site-packages\\tensorflow_core\\python\\eager\\context.py\", line 29, in <module>\n",
      "    from tensorflow.core.protobuf import config_pb2\n",
      "  File \"d:\\onedrive\\realtimeobjectdetection\\tensor\\lib\\site-packages\\tensorflow_core\\core\\protobuf\\config_pb2.py\", line 16, in <module>\n",
      "    from tensorflow.core.framework import cost_graph_pb2 as tensorflow_dot_core_dot_framework_dot_cost__graph__pb2\n",
      "  File \"d:\\onedrive\\realtimeobjectdetection\\tensor\\lib\\site-packages\\tensorflow_core\\core\\framework\\cost_graph_pb2.py\", line 16, in <module>\n",
      "    from tensorflow.core.framework import tensor_shape_pb2 as tensorflow_dot_core_dot_framework_dot_tensor__shape__pb2\n",
      "  File \"d:\\onedrive\\realtimeobjectdetection\\tensor\\lib\\site-packages\\tensorflow_core\\core\\framework\\tensor_shape_pb2.py\", line 42, in <module>\n",
      "    serialized_options=None, file=DESCRIPTOR),\n",
      "  File \"d:\\onedrive\\realtimeobjectdetection\\tensor\\lib\\site-packages\\google\\protobuf\\descriptor.py\", line 560, in __new__\n",
      "    return _message.default_pool.FindFieldByName(full_name)\n",
      "TypeError: Descriptors cannot not be created directly.\n",
      "If this call came from a _pb2.py file, your generated code is out of date and must be regenerated with protoc >= 3.19.0.\n",
      "If you cannot immediately regenerate your protos, some other possible workarounds are:\n",
      " 1. Downgrade the protobuf package to 3.20.x or lower.\n",
      " 2. Set PROTOCOL_BUFFERS_PYTHON_IMPLEMENTATION=python (but this will use pure-Python parsing and will be much slower).\n",
      "\n",
      "More information: https://developers.google.com/protocol-buffers/docs/news/2022-05-06#python-updates\n",
      "ERROR! Session/line number was not unique in database. History logging moved to new session 71\n",
      "Traceback (most recent call last):\n",
      "  File \"d:\\onedrive\\realtimeobjectdetection\\tensor\\lib\\site-packages\\IPython\\core\\interactiveshell.py\", line 3553, in run_code\n",
      "    exec(code_obj, self.user_global_ns, self.user_ns)\n",
      "  File \"C:\\Users\\HP\\AppData\\Local\\Temp\\ipykernel_9188\\3885242755.py\", line 1, in <module>\n",
      "    pipeline_config.model.ssd.num_classes = 2\n",
      "NameError: name 'pipeline_config' is not defined\n",
      "\n",
      "During handling of the above exception, another exception occurred:\n",
      "\n",
      "Traceback (most recent call last):\n",
      "  File \"d:\\onedrive\\realtimeobjectdetection\\tensor\\lib\\site-packages\\IPython\\core\\interactiveshell.py\", line 2099, in showtraceback\n",
      "    stb = value._render_traceback_()\n",
      "AttributeError: 'NameError' object has no attribute '_render_traceback_'\n",
      "\n",
      "During handling of the above exception, another exception occurred:\n",
      "\n",
      "Traceback (most recent call last):\n",
      "  File \"d:\\onedrive\\realtimeobjectdetection\\tensor\\lib\\site-packages\\IPython\\core\\interactiveshell.py\", line 3473, in run_ast_nodes\n",
      "    if (await self.run_code(code, result,  async_=asy)):\n",
      "  File \"d:\\onedrive\\realtimeobjectdetection\\tensor\\lib\\site-packages\\IPython\\core\\interactiveshell.py\", line 3575, in run_code\n",
      "    self.showtraceback(running_compiled_code=True)\n",
      "  File \"d:\\onedrive\\realtimeobjectdetection\\tensor\\lib\\site-packages\\IPython\\core\\interactiveshell.py\", line 2102, in showtraceback\n",
      "    value, tb, tb_offset=tb_offset)\n",
      "  File \"d:\\onedrive\\realtimeobjectdetection\\tensor\\lib\\site-packages\\IPython\\core\\ultratb.py\", line 1368, in structured_traceback\n",
      "    self, etype, value, tb, tb_offset, number_of_lines_of_context)\n",
      "  File \"d:\\onedrive\\realtimeobjectdetection\\tensor\\lib\\site-packages\\IPython\\core\\ultratb.py\", line 1268, in structured_traceback\n",
      "    self, etype, value, tb, tb_offset, number_of_lines_of_context\n",
      "  File \"d:\\onedrive\\realtimeobjectdetection\\tensor\\lib\\site-packages\\IPython\\core\\ultratb.py\", line 1125, in structured_traceback\n",
      "    tb_offset)\n",
      "  File \"d:\\onedrive\\realtimeobjectdetection\\tensor\\lib\\site-packages\\IPython\\core\\ultratb.py\", line 1082, in format_exception_as_a_whole\n",
      "    last_unique, recursion_repeat = find_recursion(orig_etype, evalue, records)\n",
      "  File \"d:\\onedrive\\realtimeobjectdetection\\tensor\\lib\\site-packages\\IPython\\core\\ultratb.py\", line 382, in find_recursion\n",
      "    return len(records), 0\n",
      "TypeError: object of type 'NoneType' has no len()\n",
      "\n",
      "During handling of the above exception, another exception occurred:\n",
      "\n",
      "Traceback (most recent call last):\n",
      "  File \"d:\\onedrive\\realtimeobjectdetection\\tensor\\lib\\site-packages\\IPython\\core\\interactiveshell.py\", line 2099, in showtraceback\n",
      "    stb = value._render_traceback_()\n",
      "AttributeError: 'TypeError' object has no attribute '_render_traceback_'\n",
      "\n",
      "During handling of the above exception, another exception occurred:\n",
      "\n",
      "Traceback (most recent call last):\n",
      "  File \"d:\\onedrive\\realtimeobjectdetection\\tensor\\lib\\site-packages\\IPython\\core\\interactiveshell.py\", line 3030, in _run_cell\n",
      "    return runner(coro)\n",
      "  File \"d:\\onedrive\\realtimeobjectdetection\\tensor\\lib\\site-packages\\IPython\\core\\async_helpers.py\", line 78, in _pseudo_sync_runner\n",
      "    coro.send(None)\n",
      "  File \"d:\\onedrive\\realtimeobjectdetection\\tensor\\lib\\site-packages\\IPython\\core\\interactiveshell.py\", line 3258, in run_cell_async\n",
      "    interactivity=interactivity, compiler=compiler, result=result)\n",
      "  File \"d:\\onedrive\\realtimeobjectdetection\\tensor\\lib\\site-packages\\IPython\\core\\interactiveshell.py\", line 3492, in run_ast_nodes\n",
      "    self.showtraceback()\n",
      "  File \"d:\\onedrive\\realtimeobjectdetection\\tensor\\lib\\site-packages\\IPython\\core\\interactiveshell.py\", line 2102, in showtraceback\n",
      "    value, tb, tb_offset=tb_offset)\n",
      "  File \"d:\\onedrive\\realtimeobjectdetection\\tensor\\lib\\site-packages\\IPython\\core\\ultratb.py\", line 1368, in structured_traceback\n",
      "    self, etype, value, tb, tb_offset, number_of_lines_of_context)\n",
      "  File \"d:\\onedrive\\realtimeobjectdetection\\tensor\\lib\\site-packages\\IPython\\core\\ultratb.py\", line 1268, in structured_traceback\n",
      "    self, etype, value, tb, tb_offset, number_of_lines_of_context\n",
      "  File \"d:\\onedrive\\realtimeobjectdetection\\tensor\\lib\\site-packages\\IPython\\core\\ultratb.py\", line 1143, in structured_traceback\n",
      "    chained_exceptions_tb_offset)\n",
      "  File \"d:\\onedrive\\realtimeobjectdetection\\tensor\\lib\\site-packages\\IPython\\core\\ultratb.py\", line 1082, in format_exception_as_a_whole\n",
      "    last_unique, recursion_repeat = find_recursion(orig_etype, evalue, records)\n",
      "  File \"d:\\onedrive\\realtimeobjectdetection\\tensor\\lib\\site-packages\\IPython\\core\\ultratb.py\", line 382, in find_recursion\n",
      "    return len(records), 0\n",
      "TypeError: object of type 'NoneType' has no len()\n",
      "\n",
      "During handling of the above exception, another exception occurred:\n",
      "\n",
      "Traceback (most recent call last):\n",
      "  File \"d:\\onedrive\\realtimeobjectdetection\\tensor\\lib\\site-packages\\IPython\\core\\interactiveshell.py\", line 2099, in showtraceback\n",
      "    stb = value._render_traceback_()\n",
      "AttributeError: 'TypeError' object has no attribute '_render_traceback_'\n",
      "\n",
      "During handling of the above exception, another exception occurred:\n",
      "\n",
      "Traceback (most recent call last):\n",
      "  File \"d:\\onedrive\\realtimeobjectdetection\\tensor\\lib\\site-packages\\IPython\\core\\ultratb.py\", line 1101, in get_records\n",
      "    return _fixed_getinnerframes(etb, number_of_lines_of_context, tb_offset)\n",
      "  File \"d:\\onedrive\\realtimeobjectdetection\\tensor\\lib\\site-packages\\IPython\\core\\ultratb.py\", line 248, in wrapped\n",
      "    return f(*args, **kwargs)\n",
      "  File \"d:\\onedrive\\realtimeobjectdetection\\tensor\\lib\\site-packages\\IPython\\core\\ultratb.py\", line 281, in _fixed_getinnerframes\n",
      "    records = fix_frame_records_filenames(inspect.getinnerframes(etb, context))\n",
      "  File \"C:\\python\\python37\\lib\\inspect.py\", line 1502, in getinnerframes\n",
      "    frameinfo = (tb.tb_frame,) + getframeinfo(tb, context)\n",
      "  File \"C:\\python\\python37\\lib\\inspect.py\", line 1460, in getframeinfo\n",
      "    filename = getsourcefile(frame) or getfile(frame)\n",
      "  File \"C:\\python\\python37\\lib\\inspect.py\", line 696, in getsourcefile\n",
      "    if getattr(getmodule(object, filename), '__loader__', None) is not None:\n",
      "  File \"C:\\python\\python37\\lib\\inspect.py\", line 733, in getmodule\n",
      "    if ismodule(module) and hasattr(module, '__file__'):\n",
      "  File \"d:\\onedrive\\realtimeobjectdetection\\tensor\\lib\\site-packages\\tensorflow\\__init__.py\", line 50, in __getattr__\n",
      "    module = self._load()\n",
      "  File \"d:\\onedrive\\realtimeobjectdetection\\tensor\\lib\\site-packages\\tensorflow\\__init__.py\", line 44, in _load\n",
      "    module = _importlib.import_module(self.__name__)\n",
      "  File \"C:\\python\\python37\\lib\\importlib\\__init__.py\", line 127, in import_module\n",
      "    return _bootstrap._gcd_import(name[level:], package, level)\n",
      "  File \"<frozen importlib._bootstrap>\", line 1006, in _gcd_import\n",
      "  File \"<frozen importlib._bootstrap>\", line 983, in _find_and_load\n",
      "  File \"<frozen importlib._bootstrap>\", line 953, in _find_and_load_unlocked\n",
      "  File \"<frozen importlib._bootstrap>\", line 219, in _call_with_frames_removed\n",
      "  File \"<frozen importlib._bootstrap>\", line 1006, in _gcd_import\n",
      "  File \"<frozen importlib._bootstrap>\", line 983, in _find_and_load\n",
      "  File \"<frozen importlib._bootstrap>\", line 967, in _find_and_load_unlocked\n",
      "  File \"<frozen importlib._bootstrap>\", line 677, in _load_unlocked\n",
      "  File \"<frozen importlib._bootstrap_external>\", line 728, in exec_module\n",
      "  File \"<frozen importlib._bootstrap>\", line 219, in _call_with_frames_removed\n",
      "  File \"d:\\onedrive\\realtimeobjectdetection\\tensor\\lib\\site-packages\\tensorflow_core\\__init__.py\", line 33, in <module>\n",
      "    from tensorflow._api.v1 import audio\n",
      "  File \"d:\\onedrive\\realtimeobjectdetection\\tensor\\lib\\site-packages\\tensorflow_core\\_api\\v1\\audio\\__init__.py\", line 10, in <module>\n",
      "    from tensorflow.python.ops.gen_audio_ops import decode_wav\n",
      "  File \"d:\\onedrive\\realtimeobjectdetection\\tensor\\lib\\site-packages\\tensorflow_core\\python\\ops\\gen_audio_ops.py\", line 10, in <module>\n",
      "    from tensorflow.python.eager import context as _context\n",
      "  File \"d:\\onedrive\\realtimeobjectdetection\\tensor\\lib\\site-packages\\tensorflow_core\\python\\eager\\context.py\", line 29, in <module>\n",
      "    from tensorflow.core.protobuf import config_pb2\n",
      "  File \"d:\\onedrive\\realtimeobjectdetection\\tensor\\lib\\site-packages\\tensorflow_core\\core\\protobuf\\config_pb2.py\", line 16, in <module>\n",
      "    from tensorflow.core.framework import cost_graph_pb2 as tensorflow_dot_core_dot_framework_dot_cost__graph__pb2\n",
      "  File \"d:\\onedrive\\realtimeobjectdetection\\tensor\\lib\\site-packages\\tensorflow_core\\core\\framework\\cost_graph_pb2.py\", line 16, in <module>\n",
      "    from tensorflow.core.framework import tensor_shape_pb2 as tensorflow_dot_core_dot_framework_dot_tensor__shape__pb2\n",
      "  File \"d:\\onedrive\\realtimeobjectdetection\\tensor\\lib\\site-packages\\tensorflow_core\\core\\framework\\tensor_shape_pb2.py\", line 42, in <module>\n",
      "    serialized_options=None, file=DESCRIPTOR),\n",
      "  File \"d:\\onedrive\\realtimeobjectdetection\\tensor\\lib\\site-packages\\google\\protobuf\\descriptor.py\", line 560, in __new__\n",
      "    return _message.default_pool.FindFieldByName(full_name)\n",
      "TypeError: Descriptors cannot not be created directly.\n",
      "If this call came from a _pb2.py file, your generated code is out of date and must be regenerated with protoc >= 3.19.0.\n",
      "If you cannot immediately regenerate your protos, some other possible workarounds are:\n",
      " 1. Downgrade the protobuf package to 3.20.x or lower.\n",
      " 2. Set PROTOCOL_BUFFERS_PYTHON_IMPLEMENTATION=python (but this will use pure-Python parsing and will be much slower).\n",
      "\n",
      "More information: https://developers.google.com/protocol-buffers/docs/news/2022-05-06#python-updates\n"
     ]
    }
   ],
   "source": [
    "pipeline_config.model.ssd.num_classes = 2\n",
    "pipeline_config.train_config.batch_size = 4\n",
    "pipeline_config.train_config.fine_tune_checkpoint = PRETRAINED_MODEL_PATH+'/ssd_mobilenet_v2_fpnlite_320x320_coco17_tpu-8/checkpoint/ckpt-0'\n",
    "pipeline_config.train_config.fine_tune_checkpoint_type = \"detection\"\n",
    "pipeline_config.train_input_reader.label_map_path= ANNOTATION_PATH + '/label_map.pbtxt'\n",
    "pipeline_config.train_input_reader.tf_record_input_reader.input_path[:] = [ANNOTATION_PATH + '/train.record']\n",
    "pipeline_config.eval_input_reader[0].label_map_path = ANNOTATION_PATH + '/label_map.pbtxt'\n",
    "pipeline_config.eval_input_reader[0].tf_record_input_reader.input_path[:] = [ANNOTATION_PATH + '/test.record']"
   ]
  },
  {
   "cell_type": "code",
   "execution_count": 54,
   "metadata": {},
   "outputs": [],
   "source": [
    "config_text = text_format.MessageToString(pipeline_config)                                                                                                                                                                                                        \n",
    "with tf.io.gfile.GFile(CONFIG_PATH, \"wb\") as f:                                                                                                                                                                                                                     \n",
    "    f.write(config_text)   "
   ]
  },
  {
   "cell_type": "markdown",
   "metadata": {},
   "source": [
    "# 6. Train the model"
   ]
  },
  {
   "cell_type": "code",
   "execution_count": 58,
   "metadata": {},
   "outputs": [
    {
     "name": "stdout",
     "output_type": "stream",
     "text": [
      "python Tensorflow/models/research/object_detection/model_main_tf2.py --model_dir=Tensorflow/workspace/models/my_ssd_mobnet --pipeline_config_path=Tensorflow/workspace/models/my_ssd_mobnet/pipeline.config --num_train_steps=5000\n"
     ]
    }
   ],
   "source": [
    "print(\"\"\"python {}/research/object_detection/model_main_tf2.py --model_dir={}/{} --pipeline_config_path={}/{}/pipeline.config --num_train_steps=5000\"\"\".format(APIMODEL_PATH, MODEL_PATH,CUSTOM_MODEL_NAME,MODEL_PATH,CUSTOM_MODEL_NAME))"
   ]
  },
  {
   "cell_type": "markdown",
   "metadata": {},
   "source": [
    "# 7. Load Train Model From Checkpoint"
   ]
  },
  {
   "cell_type": "code",
   "execution_count": 2,
   "metadata": {},
   "outputs": [],
   "source": [
    "import os\n",
    "from object_detection.utils import label_map_util\n",
    "from object_detection.utils import visualization_utils as viz_utils\n",
    "from object_detection.builders import model_builder"
   ]
  },
  {
   "cell_type": "code",
   "execution_count": 9,
   "metadata": {},
   "outputs": [],
   "source": [
    "# Load pipeline config and build a detection model\n",
    "configs = config_util.get_configs_from_pipeline_file(CONFIG_PATH)\n",
    "detection_model = model_builder.build(model_config=configs['model'], is_training=False)\n",
    "\n",
    "# Restore checkpoint\n",
    "ckpt = tf.compat.v2.train.Checkpoint(model=detection_model)\n",
    "ckpt.restore(os.path.join(CHECKPOINT_PATH, 'ckpt-6')).expect_partial()\n",
    "\n",
    "@tf.function\n",
    "def detect_fn(image):\n",
    "    image, shapes = detection_model.preprocess(image)\n",
    "    prediction_dict = detection_model.predict(image, shapes)\n",
    "    detections = detection_model.postprocess(prediction_dict, shapes)\n",
    "    return detections"
   ]
  },
  {
   "cell_type": "markdown",
   "metadata": {},
   "source": [
    "# 8. Detect in Real-Time"
   ]
  },
  {
   "cell_type": "code",
   "execution_count": 10,
   "metadata": {},
   "outputs": [],
   "source": [
    "import cv2 \n",
    "import numpy as np"
   ]
  },
  {
   "cell_type": "code",
   "execution_count": 11,
   "metadata": {},
   "outputs": [],
   "source": [
    "category_index = label_map_util.create_category_index_from_labelmap(ANNOTATION_PATH+'/label_map.pbtxt')"
   ]
  },
  {
   "cell_type": "code",
   "execution_count": 105,
   "metadata": {},
   "outputs": [],
   "source": [
    "cap.release()"
   ]
  },
  {
   "cell_type": "code",
   "execution_count": 12,
   "metadata": {},
   "outputs": [],
   "source": [
    "# Setup capture\n",
    "cap = cv2.VideoCapture(0)\n",
    "width = int(cap.get(cv2.CAP_PROP_FRAME_WIDTH))\n",
    "height = int(cap.get(cv2.CAP_PROP_FRAME_HEIGHT))"
   ]
  },
  {
   "cell_type": "code",
   "execution_count": null,
   "metadata": {},
   "outputs": [],
   "source": [
    "while True: \n",
    "    ret, frame = cap.read()\n",
    "    image_np = np.array(frame)\n",
    "    \n",
    "    input_tensor = tf.convert_to_tensor(np.expand_dims(image_np, 0), dtype=tf.float32)\n",
    "    detections = detect_fn(input_tensor)\n",
    "    \n",
    "    num_detections = int(detections.pop('num_detections'))\n",
    "    detections = {key: value[0, :num_detections].numpy()\n",
    "                  for key, value in detections.items()}\n",
    "    detections['num_detections'] = num_detections\n",
    "\n",
    "    # detection_classes should be ints.\n",
    "    detections['detection_classes'] = detections['detection_classes'].astype(np.int64)\n",
    "\n",
    "    label_id_offset = 1\n",
    "    image_np_with_detections = image_np.copy()\n",
    "\n",
    "    viz_utils.visualize_boxes_and_labels_on_image_array(\n",
    "                image_np_with_detections,\n",
    "                detections['detection_boxes'],\n",
    "                detections['detection_classes']+label_id_offset,\n",
    "                detections['detection_scores'],\n",
    "                category_index,\n",
    "                use_normalized_coordinates=True,\n",
    "                max_boxes_to_draw=5,\n",
    "                min_score_thresh=.5,\n",
    "                agnostic_mode=False)\n",
    "\n",
    "    cv2.imshow('object detection',  cv2.resize(image_np_with_detections, (800, 600)))\n",
    "    \n",
    "    if cv2.waitKey(1) & 0xFF == ord('q'):\n",
    "        cap.release()\n",
    "        break"
   ]
  },
  {
   "cell_type": "code",
   "execution_count": 42,
   "metadata": {},
   "outputs": [],
   "source": [
    "detections = detect_fn(input_tensor)"
   ]
  },
  {
   "cell_type": "code",
   "execution_count": 67,
   "metadata": {},
   "outputs": [],
   "source": [
    "from matplotlib import pyplot as plt"
   ]
  },
  {
   "cell_type": "code",
   "execution_count": null,
   "metadata": {},
   "outputs": [],
   "source": []
  }
 ],
 "metadata": {
  "kernelspec": {
   "display_name": "Python 3 (ipykernel)",
   "language": "python",
   "name": "python3"
  },
  "language_info": {
   "codemirror_mode": {
    "name": "ipython",
    "version": 3
   },
   "file_extension": ".py",
   "mimetype": "text/x-python",
   "name": "python",
   "nbconvert_exporter": "python",
   "pygments_lexer": "ipython3",
   "version": "3.9.4"
  },
  "vscode": {
   "interpreter": {
    "hash": "88d99ca457c047e9057600956b357b3efdb2f2a25d39cb84e275f5717fb31930"
   }
  }
 },
 "nbformat": 4,
 "nbformat_minor": 2
}
